[2024-06-04T04:59:07.837+0000] {taskinstance.py:1956} INFO - Dependencies all met for dep_context=non-requeueable deps ti=<TaskInstance: alert_2.fetch_data_task scheduled__2024-06-03T15:00:00+00:00 [queued]>
[2024-06-04T04:59:08.043+0000] {taskinstance.py:1956} INFO - Dependencies all met for dep_context=requeueable deps ti=<TaskInstance: alert_2.fetch_data_task scheduled__2024-06-03T15:00:00+00:00 [queued]>
[2024-06-04T04:59:08.101+0000] {taskinstance.py:2170} INFO - Starting attempt 1 of 2
[2024-06-04T04:59:09.036+0000] {taskinstance.py:2191} INFO - Executing <Task(PythonOperator): fetch_data_task> on 2024-06-03 15:00:00+00:00
[2024-06-04T04:59:09.069+0000] {standard_task_runner.py:60} INFO - Started process 303 to run task
[2024-06-04T04:59:09.182+0000] {standard_task_runner.py:87} INFO - Running: ['***', 'tasks', 'run', 'alert_2', 'fetch_data_task', 'scheduled__2024-06-03T15:00:00+00:00', '--job-id', '936', '--raw', '--subdir', 'DAGS_FOLDER/alert_2.py', '--cfg-path', '/tmp/tmpvu3fndkm']
[2024-06-04T04:59:09.222+0000] {standard_task_runner.py:88} INFO - Job 936: Subtask fetch_data_task
[2024-06-04T04:59:10.137+0000] {task_command.py:423} INFO - Running <TaskInstance: alert_2.fetch_data_task scheduled__2024-06-03T15:00:00+00:00 [running]> on host e8d24771e2f4
[2024-06-04T04:59:11.494+0000] {taskinstance.py:2480} INFO - Exporting env vars: AIRFLOW_CTX_DAG_OWNER='***' AIRFLOW_CTX_DAG_ID='alert_2' AIRFLOW_CTX_TASK_ID='fetch_data_task' AIRFLOW_CTX_EXECUTION_DATE='2024-06-03T15:00:00+00:00' AIRFLOW_CTX_TRY_NUMBER='1' AIRFLOW_CTX_DAG_RUN_ID='scheduled__2024-06-03T15:00:00+00:00'
[2024-06-04T04:59:11.666+0000] {connection.py:234} WARNING - Connection schemes (type: google_cloud_platform) shall not contain '_' according to RFC3986.
[2024-06-04T04:59:11.759+0000] {base.py:83} INFO - Using connection ID 'google_cloud_default' for task execution.
[2024-06-04T04:59:12.384+0000] {bigquery.py:1596} INFO - Inserting job ***_1717477152372178_3d46d0678e14a8bd27bc7a1f70b9be68
[2024-06-04T04:59:21.785+0000] {taskinstance.py:2698} ERROR - Task failed with exception
Traceback (most recent call last):
  File "/home/airflow/.local/lib/python3.8/site-packages/airflow/models/taskinstance.py", line 433, in _execute_task
    result = execute_callable(context=context, **execute_callable_kwargs)
  File "/home/airflow/.local/lib/python3.8/site-packages/airflow/operators/python.py", line 199, in execute
    return_value = self.execute_callable()
  File "/home/airflow/.local/lib/python3.8/site-packages/airflow/operators/python.py", line 216, in execute_callable
    return self.python_callable(*self.op_args, **self.op_kwargs)
  File "/opt/airflow/dags/alert_2.py", line 28, in fetch_data_from_bigquery
    cursor.execute(sql_query)
  File "/home/airflow/.local/lib/python3.8/site-packages/airflow/providers/google/cloud/hooks/bigquery.py", line 2779, in execute
    self.job_id = self._run_query(sql)
  File "/home/airflow/.local/lib/python3.8/site-packages/airflow/providers/google/cloud/hooks/bigquery.py", line 2927, in _run_query
    job = self.hook.insert_job(configuration=configuration, project_id=self.project_id, location=location)
  File "/home/airflow/.local/lib/python3.8/site-packages/airflow/providers/google/common/hooks/base_google.py", line 477, in inner_wrapper
    return func(self, *args, **kwargs)
  File "/home/airflow/.local/lib/python3.8/site-packages/airflow/providers/google/cloud/hooks/bigquery.py", line 1602, in insert_job
    job_api_repr.result(timeout=timeout, retry=retry)
  File "/home/airflow/.local/lib/python3.8/site-packages/google/cloud/bigquery/job/query.py", line 1595, in result
    do_get_result()
  File "/home/airflow/.local/lib/python3.8/site-packages/google/cloud/bigquery/job/query.py", line 1584, in do_get_result
    super(QueryJob, self).result(retry=retry, timeout=timeout)
  File "/home/airflow/.local/lib/python3.8/site-packages/google/cloud/bigquery/job/base.py", line 971, in result
    return super(_AsyncJob, self).result(timeout=timeout, **kwargs)
  File "/home/airflow/.local/lib/python3.8/site-packages/google/api_core/future/polling.py", line 261, in result
    raise self._exception
google.api_core.exceptions.BadRequest: 400 Encountered " "-" "- "" at line 1, column 22.
Was expecting:
    <EOF>
[Try using standard SQL (https://cloud.google.com/bigquery/docs/reference/standard-sql/enabling-standard-sql)]; reason: invalidQuery, location: query, message: Encountered " "-" "- "" at line 1, column 22.
Was expecting:
    <EOF>
[Try using standard SQL (https://cloud.google.com/bigquery/docs/reference/standard-sql/enabling-standard-sql)]

Location: US
Job ID: airflow_1717477152372178_3d46d0678e14a8bd27bc7a1f70b9be68

[2024-06-04T04:59:21.909+0000] {taskinstance.py:1138} INFO - Marking task as UP_FOR_RETRY. dag_id=alert_2, task_id=fetch_data_task, execution_date=20240603T150000, start_date=20240604T045907, end_date=20240604T045921
[2024-06-04T04:59:22.051+0000] {standard_task_runner.py:107} ERROR - Failed to execute job 936 for task fetch_data_task (400 Encountered " "-" "- "" at line 1, column 22.
Was expecting:
    <EOF>
[Try using standard SQL (https://cloud.google.com/bigquery/docs/reference/standard-sql/enabling-standard-sql)]; reason: invalidQuery, location: query, message: Encountered " "-" "- "" at line 1, column 22.
Was expecting:
    <EOF>
[Try using standard SQL (https://cloud.google.com/bigquery/docs/reference/standard-sql/enabling-standard-sql)]

Location: US
Job ID: airflow_1717477152372178_3d46d0678e14a8bd27bc7a1f70b9be68
; 303)
[2024-06-04T04:59:22.128+0000] {local_task_job_runner.py:234} INFO - Task exited with return code 1
[2024-06-04T04:59:22.394+0000] {taskinstance.py:3280} INFO - 0 downstream tasks scheduled from follow-on schedule check
