[2024-05-30T04:44:10.410+0000] {taskinstance.py:1956} INFO - Dependencies all met for dep_context=non-requeueable deps ti=<TaskInstance: dbt_run.dbt_run manual__2024-05-30T04:44:08.056907+00:00 [queued]>
[2024-05-30T04:44:10.421+0000] {taskinstance.py:1956} INFO - Dependencies all met for dep_context=requeueable deps ti=<TaskInstance: dbt_run.dbt_run manual__2024-05-30T04:44:08.056907+00:00 [queued]>
[2024-05-30T04:44:10.422+0000] {taskinstance.py:2170} INFO - Starting attempt 1 of 1
[2024-05-30T04:44:10.442+0000] {taskinstance.py:2191} INFO - Executing <Task(PythonOperator): dbt_run> on 2024-05-30 04:44:08.056907+00:00
[2024-05-30T04:44:10.450+0000] {standard_task_runner.py:60} INFO - Started process 25021 to run task
[2024-05-30T04:44:10.456+0000] {standard_task_runner.py:87} INFO - Running: ['***', 'tasks', 'run', 'dbt_run', 'dbt_run', 'manual__2024-05-30T04:44:08.056907+00:00', '--job-id', '405', '--raw', '--subdir', 'DAGS_FOLDER/dbt_run.py', '--cfg-path', '/tmp/tmpjlm2ug92']
[2024-05-30T04:44:10.459+0000] {standard_task_runner.py:88} INFO - Job 405: Subtask dbt_run
[2024-05-30T04:44:10.514+0000] {task_command.py:423} INFO - Running <TaskInstance: dbt_run.dbt_run manual__2024-05-30T04:44:08.056907+00:00 [running]> on host dd00f1ab2b6c
[2024-05-30T04:44:10.609+0000] {taskinstance.py:2480} INFO - Exporting env vars: AIRFLOW_CTX_DAG_OWNER='***' AIRFLOW_CTX_DAG_ID='dbt_run' AIRFLOW_CTX_TASK_ID='dbt_run' AIRFLOW_CTX_EXECUTION_DATE='2024-05-30T04:44:08.056907+00:00' AIRFLOW_CTX_TRY_NUMBER='1' AIRFLOW_CTX_DAG_RUN_ID='manual__2024-05-30T04:44:08.056907+00:00'
[2024-05-30T04:44:10.611+0000] {taskinstance.py:2698} ERROR - Task failed with exception
Traceback (most recent call last):
  File "/home/airflow/.local/lib/python3.8/site-packages/airflow/models/taskinstance.py", line 433, in _execute_task
    result = execute_callable(context=context, **execute_callable_kwargs)
  File "/home/airflow/.local/lib/python3.8/site-packages/airflow/operators/python.py", line 199, in execute
    return_value = self.execute_callable()
  File "/home/airflow/.local/lib/python3.8/site-packages/airflow/operators/python.py", line 216, in execute_callable
    return self.python_callable(*self.op_args, **self.op_kwargs)
  File "/opt/airflow/dags/dbt_run.py", line 16, in run_dbt
    os.chdir(DBT_PROJECT_PATH)
FileNotFoundError: [Errno 2] No such file or directory: 'dbt/network'
[2024-05-30T04:44:10.627+0000] {taskinstance.py:1138} INFO - Marking task as FAILED. dag_id=dbt_run, task_id=dbt_run, execution_date=20240530T044408, start_date=20240530T044410, end_date=20240530T044410
[2024-05-30T04:44:10.643+0000] {standard_task_runner.py:107} ERROR - Failed to execute job 405 for task dbt_run ([Errno 2] No such file or directory: 'dbt/network'; 25021)
[2024-05-30T04:44:10.670+0000] {local_task_job_runner.py:234} INFO - Task exited with return code 1
[2024-05-30T04:44:10.691+0000] {taskinstance.py:3280} INFO - 0 downstream tasks scheduled from follow-on schedule check
