[2024-06-05T07:35:37.029+0000] {taskinstance.py:1956} INFO - Dependencies all met for dep_context=non-requeueable deps ti=<TaskInstance: bigquery_transform_python.run_transform_script manual__2024-06-04T15:12:02.201698+00:00 [queued]>
[2024-06-05T07:35:37.049+0000] {taskinstance.py:1956} INFO - Dependencies all met for dep_context=requeueable deps ti=<TaskInstance: bigquery_transform_python.run_transform_script manual__2024-06-04T15:12:02.201698+00:00 [queued]>
[2024-06-05T07:35:37.050+0000] {taskinstance.py:2170} INFO - Starting attempt 2 of 2
[2024-06-05T07:35:37.101+0000] {taskinstance.py:2191} INFO - Executing <Task(PythonOperator): run_transform_script> on 2024-06-04 15:12:02.201698+00:00
[2024-06-05T07:35:37.137+0000] {standard_task_runner.py:60} INFO - Started process 252 to run task
[2024-06-05T07:35:37.406+0000] {standard_task_runner.py:87} INFO - Running: ['***', 'tasks', 'run', 'bigquery_transform_python', 'run_transform_script', 'manual__2024-06-04T15:12:02.201698+00:00', '--job-id', '1074', '--raw', '--subdir', 'DAGS_FOLDER/bigquery_transform_python.py', '--cfg-path', '/tmp/tmp9rab3rtt']
[2024-06-05T07:35:37.421+0000] {standard_task_runner.py:88} INFO - Job 1074: Subtask run_transform_script
[2024-06-05T07:35:37.733+0000] {task_command.py:423} INFO - Running <TaskInstance: bigquery_transform_python.run_transform_script manual__2024-06-04T15:12:02.201698+00:00 [running]> on host e98391521b34
[2024-06-05T07:35:38.047+0000] {taskinstance.py:2480} INFO - Exporting env vars: AIRFLOW_CTX_DAG_OWNER='***' AIRFLOW_CTX_DAG_ID='bigquery_transform_python' AIRFLOW_CTX_TASK_ID='run_transform_script' AIRFLOW_CTX_EXECUTION_DATE='2024-06-04T15:12:02.201698+00:00' AIRFLOW_CTX_TRY_NUMBER='2' AIRFLOW_CTX_DAG_RUN_ID='manual__2024-06-04T15:12:02.201698+00:00'
[2024-06-05T07:35:52.444+0000] {logging_mixin.py:188} INFO - Traceback (most recent call last):
  File "/opt/***/dags/network_model/dataprep.py", line 8, in <module>
    client = bigquery.Client()
  File "/home/***/.local/lib/python3.8/site-packages/google/cloud/bigquery/client.py", line 237, in __init__
    super(Client, self).__init__(
  File "/home/***/.local/lib/python3.8/site-packages/google/cloud/client/__init__.py", line 320, in __init__
    _ClientProjectMixin.__init__(self, project=project, credentials=credentials)
  File "/home/***/.local/lib/python3.8/site-packages/google/cloud/client/__init__.py", line 268, in __init__
    project = self._determine_default(project)
  File "/home/***/.local/lib/python3.8/site-packages/google/cloud/client/__init__.py", line 287, in _determine_default
    return _determine_default_project(project)
  File "/home/***/.local/lib/python3.8/site-packages/google/cloud/_helpers/__init__.py", line 152, in _determine_default_project
    _, project = google.auth.default()
  File "/home/***/.local/lib/python3.8/site-packages/google/auth/_default.py", line 691, in default
    raise exceptions.DefaultCredentialsError(_CLOUD_SDK_MISSING_CREDENTIALS)
google.auth.exceptions.DefaultCredentialsError: Your default credentials were not found. To set up Application Default Credentials, see https://cloud.google.com/docs/authentication/external/set-up-adc for more information.
[2024-06-05T07:35:52.590+0000] {taskinstance.py:2698} ERROR - Task failed with exception
Traceback (most recent call last):
  File "/home/airflow/.local/lib/python3.8/site-packages/airflow/models/taskinstance.py", line 433, in _execute_task
    result = execute_callable(context=context, **execute_callable_kwargs)
  File "/home/airflow/.local/lib/python3.8/site-packages/airflow/operators/python.py", line 199, in execute
    return_value = self.execute_callable()
  File "/home/airflow/.local/lib/python3.8/site-packages/airflow/operators/python.py", line 216, in execute_callable
    return self.python_callable(*self.op_args, **self.op_kwargs)
  File "/opt/airflow/dags/bigquery_transform_python.py", line 26, in run_transform_script
    raise Exception("Script failed: " + result.stderr)
Exception: Script failed: Traceback (most recent call last):
  File "/opt/***/dags/network_model/dataprep.py", line 8, in <module>
    client = bigquery.Client()
  File "/home/***/.local/lib/python3.8/site-packages/google/cloud/bigquery/client.py", line 237, in __init__
    super(Client, self).__init__(
  File "/home/***/.local/lib/python3.8/site-packages/google/cloud/client/__init__.py", line 320, in __init__
    _ClientProjectMixin.__init__(self, project=project, credentials=credentials)
  File "/home/***/.local/lib/python3.8/site-packages/google/cloud/client/__init__.py", line 268, in __init__
    project = self._determine_default(project)
  File "/home/***/.local/lib/python3.8/site-packages/google/cloud/client/__init__.py", line 287, in _determine_default
    return _determine_default_project(project)
  File "/home/***/.local/lib/python3.8/site-packages/google/cloud/_helpers/__init__.py", line 152, in _determine_default_project
    _, project = google.auth.default()
  File "/home/***/.local/lib/python3.8/site-packages/google/auth/_default.py", line 691, in default
    raise exceptions.DefaultCredentialsError(_CLOUD_SDK_MISSING_CREDENTIALS)
google.auth.exceptions.DefaultCredentialsError: Your default credentials were not found. To set up Application Default Credentials, see https://cloud.google.com/docs/authentication/external/set-up-adc for more information.

[2024-06-05T07:35:53.762+0000] {taskinstance.py:1138} INFO - Marking task as FAILED. dag_id=bigquery_transform_python, task_id=run_transform_script, execution_date=20240604T151202, start_date=20240605T073537, end_date=20240605T073553
[2024-06-05T07:35:55.243+0000] {standard_task_runner.py:107} ERROR - Failed to execute job 1074 for task run_transform_script (Script failed: Traceback (most recent call last):
  File "/opt/***/dags/network_model/dataprep.py", line 8, in <module>
    client = bigquery.Client()
  File "/home/***/.local/lib/python3.8/site-packages/google/cloud/bigquery/client.py", line 237, in __init__
    super(Client, self).__init__(
  File "/home/***/.local/lib/python3.8/site-packages/google/cloud/client/__init__.py", line 320, in __init__
    _ClientProjectMixin.__init__(self, project=project, credentials=credentials)
  File "/home/***/.local/lib/python3.8/site-packages/google/cloud/client/__init__.py", line 268, in __init__
    project = self._determine_default(project)
  File "/home/***/.local/lib/python3.8/site-packages/google/cloud/client/__init__.py", line 287, in _determine_default
    return _determine_default_project(project)
  File "/home/***/.local/lib/python3.8/site-packages/google/cloud/_helpers/__init__.py", line 152, in _determine_default_project
    _, project = google.auth.default()
  File "/home/***/.local/lib/python3.8/site-packages/google/auth/_default.py", line 691, in default
    raise exceptions.DefaultCredentialsError(_CLOUD_SDK_MISSING_CREDENTIALS)
google.auth.exceptions.DefaultCredentialsError: Your default credentials were not found. To set up Application Default Credentials, see https://cloud.google.com/docs/authentication/external/set-up-adc for more information.
; 252)
[2024-06-05T07:35:55.295+0000] {local_task_job_runner.py:234} INFO - Task exited with return code 1
[2024-06-05T07:35:56.613+0000] {taskinstance.py:3280} INFO - 0 downstream tasks scheduled from follow-on schedule check
