[2024-06-02T08:00:04.627+0000] {taskinstance.py:1956} INFO - Dependencies all met for dep_context=non-requeueable deps ti=<TaskInstance: anomaly_detection_and_alerting.send_alert scheduled__2024-06-02T07:00:00+00:00 [queued]>
[2024-06-02T08:00:04.646+0000] {taskinstance.py:1956} INFO - Dependencies all met for dep_context=requeueable deps ti=<TaskInstance: anomaly_detection_and_alerting.send_alert scheduled__2024-06-02T07:00:00+00:00 [queued]>
[2024-06-02T08:00:04.647+0000] {taskinstance.py:2170} INFO - Starting attempt 1 of 2
[2024-06-02T08:00:04.671+0000] {taskinstance.py:2191} INFO - Executing <Task(PythonOperator): send_alert> on 2024-06-02 07:00:00+00:00
[2024-06-02T08:00:04.678+0000] {standard_task_runner.py:60} INFO - Started process 11922 to run task
[2024-06-02T08:00:04.683+0000] {standard_task_runner.py:87} INFO - Running: ['***', 'tasks', 'run', 'anomaly_detection_and_alerting', 'send_alert', 'scheduled__2024-06-02T07:00:00+00:00', '--job-id', '647', '--raw', '--subdir', 'DAGS_FOLDER/alert.py', '--cfg-path', '/tmp/tmprx32rzf7']
[2024-06-02T08:00:04.687+0000] {standard_task_runner.py:88} INFO - Job 647: Subtask send_alert
[2024-06-02T08:00:04.774+0000] {task_command.py:423} INFO - Running <TaskInstance: anomaly_detection_and_alerting.send_alert scheduled__2024-06-02T07:00:00+00:00 [running]> on host a6037dcd62c1
[2024-06-02T08:00:04.914+0000] {taskinstance.py:2480} INFO - Exporting env vars: AIRFLOW_CTX_DAG_OWNER='***' AIRFLOW_CTX_DAG_ID='anomaly_detection_and_alerting' AIRFLOW_CTX_TASK_ID='send_alert' AIRFLOW_CTX_EXECUTION_DATE='2024-06-02T07:00:00+00:00' AIRFLOW_CTX_TRY_NUMBER='1' AIRFLOW_CTX_DAG_RUN_ID='scheduled__2024-06-02T07:00:00+00:00'
[2024-06-02T08:00:04.938+0000] {taskinstance.py:2698} ERROR - Task failed with exception
Traceback (most recent call last):
  File "/home/airflow/.local/lib/python3.8/site-packages/airflow/models/taskinstance.py", line 433, in _execute_task
    result = execute_callable(context=context, **execute_callable_kwargs)
  File "/home/airflow/.local/lib/python3.8/site-packages/airflow/operators/python.py", line 199, in execute
    return_value = self.execute_callable()
  File "/home/airflow/.local/lib/python3.8/site-packages/airflow/operators/python.py", line 216, in execute_callable
    return self.python_callable(*self.op_args, **self.op_kwargs)
  File "/opt/airflow/dags/alert.py", line 53, in send_alert
    html_content=f"<p>Anomalies detected:</p><pre>{anomaly_details}</pre>",
NameError: name 'anomaly_details' is not defined
[2024-06-02T08:00:04.958+0000] {taskinstance.py:1138} INFO - Marking task as UP_FOR_RETRY. dag_id=anomaly_detection_and_alerting, task_id=send_alert, execution_date=20240602T070000, start_date=20240602T080004, end_date=20240602T080004
[2024-06-02T08:00:04.979+0000] {standard_task_runner.py:107} ERROR - Failed to execute job 647 for task send_alert (name 'anomaly_details' is not defined; 11922)
[2024-06-02T08:00:05.018+0000] {local_task_job_runner.py:234} INFO - Task exited with return code 1
[2024-06-02T08:00:05.045+0000] {taskinstance.py:3280} INFO - 0 downstream tasks scheduled from follow-on schedule check
