[2024-05-29T13:50:18.488+0000] {taskinstance.py:1956} INFO - Dependencies all met for dep_context=non-requeueable deps ti=<TaskInstance: dbt_test.run_dbt_model manual__2024-05-29T13:45:12.299113+00:00 [queued]>
[2024-05-29T13:50:18.505+0000] {taskinstance.py:1956} INFO - Dependencies all met for dep_context=requeueable deps ti=<TaskInstance: dbt_test.run_dbt_model manual__2024-05-29T13:45:12.299113+00:00 [queued]>
[2024-05-29T13:50:18.506+0000] {taskinstance.py:2170} INFO - Starting attempt 2 of 2
[2024-05-29T13:50:18.530+0000] {taskinstance.py:2191} INFO - Executing <Task(BashOperator): run_dbt_model> on 2024-05-29 13:45:12.299113+00:00
[2024-05-29T13:50:18.537+0000] {standard_task_runner.py:60} INFO - Started process 2790 to run task
[2024-05-29T13:50:18.540+0000] {standard_task_runner.py:87} INFO - Running: ['***', 'tasks', 'run', 'dbt_test', 'run_dbt_model', 'manual__2024-05-29T13:45:12.299113+00:00', '--job-id', '358', '--raw', '--subdir', 'DAGS_FOLDER/dbt_test.py', '--cfg-path', '/tmp/tmprc69iv3u']
[2024-05-29T13:50:18.542+0000] {standard_task_runner.py:88} INFO - Job 358: Subtask run_dbt_model
[2024-05-29T13:50:18.605+0000] {task_command.py:423} INFO - Running <TaskInstance: dbt_test.run_dbt_model manual__2024-05-29T13:45:12.299113+00:00 [running]> on host be0574dd2df3
[2024-05-29T13:50:18.718+0000] {taskinstance.py:2480} INFO - Exporting env vars: AIRFLOW_CTX_DAG_OWNER='***' AIRFLOW_CTX_DAG_ID='dbt_test' AIRFLOW_CTX_TASK_ID='run_dbt_model' AIRFLOW_CTX_EXECUTION_DATE='2024-05-29T13:45:12.299113+00:00' AIRFLOW_CTX_TRY_NUMBER='2' AIRFLOW_CTX_DAG_RUN_ID='manual__2024-05-29T13:45:12.299113+00:00'
[2024-05-29T13:50:18.721+0000] {subprocess.py:63} INFO - Tmp dir root location: /tmp
[2024-05-29T13:50:18.723+0000] {subprocess.py:75} INFO - Running command: ['/usr/bin/bash', '-c', 'cd C:/learn-dbt/learndbt  && dbt run --models clean_network']
[2024-05-29T13:50:18.738+0000] {subprocess.py:86} INFO - Output:
[2024-05-29T13:50:18.753+0000] {subprocess.py:93} INFO - /usr/bin/bash: line 1: cd: C:/learn-dbt/learndbt: No such file or directory
[2024-05-29T13:50:18.755+0000] {subprocess.py:97} INFO - Command exited with return code 1
[2024-05-29T13:50:18.769+0000] {taskinstance.py:2698} ERROR - Task failed with exception
Traceback (most recent call last):
  File "/home/airflow/.local/lib/python3.8/site-packages/airflow/models/taskinstance.py", line 433, in _execute_task
    result = execute_callable(context=context, **execute_callable_kwargs)
  File "/home/airflow/.local/lib/python3.8/site-packages/airflow/operators/bash.py", line 212, in execute
    raise AirflowException(
airflow.exceptions.AirflowException: Bash command failed. The command returned a non-zero exit code 1.
[2024-05-29T13:50:18.774+0000] {taskinstance.py:1138} INFO - Marking task as FAILED. dag_id=dbt_test, task_id=run_dbt_model, execution_date=20240529T134512, start_date=20240529T135018, end_date=20240529T135018
[2024-05-29T13:50:18.796+0000] {standard_task_runner.py:107} ERROR - Failed to execute job 358 for task run_dbt_model (Bash command failed. The command returned a non-zero exit code 1.; 2790)
[2024-05-29T13:50:18.838+0000] {local_task_job_runner.py:234} INFO - Task exited with return code 1
[2024-05-29T13:50:18.857+0000] {taskinstance.py:3280} INFO - 0 downstream tasks scheduled from follow-on schedule check
