[2024-06-03T15:20:02.716+0000] {taskinstance.py:1956} INFO - Dependencies all met for dep_context=non-requeueable deps ti=<TaskInstance: alert_2.fetch_data_task scheduled__2024-06-03T07:00:00+00:00 [queued]>
[2024-06-03T15:20:02.734+0000] {taskinstance.py:1956} INFO - Dependencies all met for dep_context=requeueable deps ti=<TaskInstance: alert_2.fetch_data_task scheduled__2024-06-03T07:00:00+00:00 [queued]>
[2024-06-03T15:20:02.736+0000] {taskinstance.py:2170} INFO - Starting attempt 2 of 2
[2024-06-03T15:20:02.758+0000] {taskinstance.py:2191} INFO - Executing <Task(PythonOperator): fetch_data_task> on 2024-06-03 07:00:00+00:00
[2024-06-03T15:20:02.770+0000] {standard_task_runner.py:60} INFO - Started process 4802 to run task
[2024-06-03T15:20:02.773+0000] {standard_task_runner.py:87} INFO - Running: ['***', 'tasks', 'run', 'alert_2', 'fetch_data_task', 'scheduled__2024-06-03T07:00:00+00:00', '--job-id', '921', '--raw', '--subdir', 'DAGS_FOLDER/alert_2.py', '--cfg-path', '/tmp/tmpuqlwhp4d']
[2024-06-03T15:20:02.776+0000] {standard_task_runner.py:88} INFO - Job 921: Subtask fetch_data_task
[2024-06-03T15:20:02.870+0000] {task_command.py:423} INFO - Running <TaskInstance: alert_2.fetch_data_task scheduled__2024-06-03T07:00:00+00:00 [running]> on host c6bf4ffbfe57
[2024-06-03T15:20:02.984+0000] {taskinstance.py:2480} INFO - Exporting env vars: AIRFLOW_CTX_DAG_OWNER='***' AIRFLOW_CTX_DAG_ID='alert_2' AIRFLOW_CTX_TASK_ID='fetch_data_task' AIRFLOW_CTX_EXECUTION_DATE='2024-06-03T07:00:00+00:00' AIRFLOW_CTX_TRY_NUMBER='2' AIRFLOW_CTX_DAG_RUN_ID='scheduled__2024-06-03T07:00:00+00:00'
[2024-06-03T15:20:02.999+0000] {connection.py:234} WARNING - Connection schemes (type: google_cloud_platform) shall not contain '_' according to RFC3986.
[2024-06-03T15:20:03.005+0000] {base.py:83} INFO - Using connection ID 'google_cloud_default' for task execution.
[2024-06-03T15:20:03.065+0000] {bigquery.py:1596} INFO - Inserting job ***_1717428003064783_b4c8d6e451d253cee3d65ac0ac409565
[2024-06-03T15:20:09.978+0000] {taskinstance.py:2698} ERROR - Task failed with exception
Traceback (most recent call last):
  File "/home/airflow/.local/lib/python3.8/site-packages/airflow/models/taskinstance.py", line 433, in _execute_task
    result = execute_callable(context=context, **execute_callable_kwargs)
  File "/home/airflow/.local/lib/python3.8/site-packages/airflow/operators/python.py", line 199, in execute
    return_value = self.execute_callable()
  File "/home/airflow/.local/lib/python3.8/site-packages/airflow/operators/python.py", line 216, in execute_callable
    return self.python_callable(*self.op_args, **self.op_kwargs)
  File "/opt/airflow/dags/alert_2.py", line 28, in fetch_data_from_bigquery
    cursor.execute(sql_query)
  File "/home/airflow/.local/lib/python3.8/site-packages/airflow/providers/google/cloud/hooks/bigquery.py", line 2779, in execute
    self.job_id = self._run_query(sql)
  File "/home/airflow/.local/lib/python3.8/site-packages/airflow/providers/google/cloud/hooks/bigquery.py", line 2927, in _run_query
    job = self.hook.insert_job(configuration=configuration, project_id=self.project_id, location=location)
  File "/home/airflow/.local/lib/python3.8/site-packages/airflow/providers/google/common/hooks/base_google.py", line 477, in inner_wrapper
    return func(self, *args, **kwargs)
  File "/home/airflow/.local/lib/python3.8/site-packages/airflow/providers/google/cloud/hooks/bigquery.py", line 1602, in insert_job
    job_api_repr.result(timeout=timeout, retry=retry)
  File "/home/airflow/.local/lib/python3.8/site-packages/google/cloud/bigquery/job/query.py", line 1595, in result
    do_get_result()
  File "/home/airflow/.local/lib/python3.8/site-packages/google/cloud/bigquery/job/query.py", line 1584, in do_get_result
    super(QueryJob, self).result(retry=retry, timeout=timeout)
  File "/home/airflow/.local/lib/python3.8/site-packages/google/cloud/bigquery/job/base.py", line 971, in result
    return super(_AsyncJob, self).result(timeout=timeout, **kwargs)
  File "/home/airflow/.local/lib/python3.8/site-packages/google/api_core/future/polling.py", line 261, in result
    raise self._exception
google.api_core.exceptions.NotFound: 404 Not found: Dataset stately-node-363801:your_dataset was not found in location US; reason: notFound, message: Not found: Dataset stately-node-363801:your_dataset was not found in location US

Location: US
Job ID: airflow_1717428003064783_b4c8d6e451d253cee3d65ac0ac409565

[2024-06-03T15:20:09.998+0000] {taskinstance.py:1138} INFO - Marking task as FAILED. dag_id=alert_2, task_id=fetch_data_task, execution_date=20240603T070000, start_date=20240603T152002, end_date=20240603T152009
[2024-06-03T15:20:10.014+0000] {standard_task_runner.py:107} ERROR - Failed to execute job 921 for task fetch_data_task (404 Not found: Dataset stately-node-363801:your_dataset was not found in location US; reason: notFound, message: Not found: Dataset stately-node-363801:your_dataset was not found in location US

Location: US
Job ID: airflow_1717428003064783_b4c8d6e451d253cee3d65ac0ac409565
; 4802)
[2024-06-03T15:20:10.040+0000] {local_task_job_runner.py:234} INFO - Task exited with return code 1
[2024-06-03T15:20:10.064+0000] {taskinstance.py:3280} INFO - 0 downstream tasks scheduled from follow-on schedule check
