[2024-05-30T03:09:50.815+0000] {taskinstance.py:1956} INFO - Dependencies all met for dep_context=non-requeueable deps ti=<TaskInstance: dbt.dbt_run manual__2024-05-30T03:09:48.477437+00:00 [queued]>
[2024-05-30T03:09:50.836+0000] {taskinstance.py:1956} INFO - Dependencies all met for dep_context=requeueable deps ti=<TaskInstance: dbt.dbt_run manual__2024-05-30T03:09:48.477437+00:00 [queued]>
[2024-05-30T03:09:50.836+0000] {taskinstance.py:2170} INFO - Starting attempt 1 of 2
[2024-05-30T03:09:50.867+0000] {taskinstance.py:2191} INFO - Executing <Task(BashOperator): dbt_run> on 2024-05-30 03:09:48.477437+00:00
[2024-05-30T03:09:50.876+0000] {standard_task_runner.py:60} INFO - Started process 11832 to run task
[2024-05-30T03:09:50.881+0000] {standard_task_runner.py:87} INFO - Running: ['***', 'tasks', 'run', 'dbt', 'dbt_run', 'manual__2024-05-30T03:09:48.477437+00:00', '--job-id', '402', '--raw', '--subdir', 'DAGS_FOLDER/dbt.py', '--cfg-path', '/tmp/tmp3y2v0cbo']
[2024-05-30T03:09:50.885+0000] {standard_task_runner.py:88} INFO - Job 402: Subtask dbt_run
[2024-05-30T03:09:50.961+0000] {task_command.py:423} INFO - Running <TaskInstance: dbt.dbt_run manual__2024-05-30T03:09:48.477437+00:00 [running]> on host dd00f1ab2b6c
[2024-05-30T03:09:51.085+0000] {taskinstance.py:2480} INFO - Exporting env vars: AIRFLOW_CTX_DAG_OWNER='***' AIRFLOW_CTX_DAG_ID='dbt' AIRFLOW_CTX_TASK_ID='dbt_run' AIRFLOW_CTX_EXECUTION_DATE='2024-05-30T03:09:48.477437+00:00' AIRFLOW_CTX_TRY_NUMBER='1' AIRFLOW_CTX_DAG_RUN_ID='manual__2024-05-30T03:09:48.477437+00:00'
[2024-05-30T03:09:51.089+0000] {subprocess.py:63} INFO - Tmp dir root location: /tmp
[2024-05-30T03:09:51.094+0000] {subprocess.py:75} INFO - Running command: ['/usr/bin/bash', '-c', 'dbt run --project-dir C:/***/dags/dbt/network']
[2024-05-30T03:09:51.109+0000] {subprocess.py:86} INFO - Output:
[2024-05-30T03:09:51.121+0000] {subprocess.py:93} INFO - /usr/bin/bash: line 1: dbt: command not found
[2024-05-30T03:09:51.122+0000] {subprocess.py:97} INFO - Command exited with return code 127
[2024-05-30T03:09:51.135+0000] {taskinstance.py:2698} ERROR - Task failed with exception
Traceback (most recent call last):
  File "/home/airflow/.local/lib/python3.8/site-packages/airflow/models/taskinstance.py", line 433, in _execute_task
    result = execute_callable(context=context, **execute_callable_kwargs)
  File "/home/airflow/.local/lib/python3.8/site-packages/airflow/operators/bash.py", line 212, in execute
    raise AirflowException(
airflow.exceptions.AirflowException: Bash command failed. The command returned a non-zero exit code 127.
[2024-05-30T03:09:51.140+0000] {taskinstance.py:1138} INFO - Marking task as UP_FOR_RETRY. dag_id=dbt, task_id=dbt_run, execution_date=20240530T030948, start_date=20240530T030950, end_date=20240530T030951
[2024-05-30T03:09:51.161+0000] {standard_task_runner.py:107} ERROR - Failed to execute job 402 for task dbt_run (Bash command failed. The command returned a non-zero exit code 127.; 11832)
[2024-05-30T03:09:51.182+0000] {local_task_job_runner.py:234} INFO - Task exited with return code 1
[2024-05-30T03:09:51.202+0000] {taskinstance.py:3280} INFO - 0 downstream tasks scheduled from follow-on schedule check
