[2024-06-01T12:54:36.895+0000] {taskinstance.py:1956} INFO - Dependencies all met for dep_context=non-requeueable deps ti=<TaskInstance: anomaly_detection_and_alerting.send_alert scheduled__2024-05-31T19:00:00+00:00 [queued]>
[2024-06-01T12:54:36.924+0000] {taskinstance.py:1956} INFO - Dependencies all met for dep_context=requeueable deps ti=<TaskInstance: anomaly_detection_and_alerting.send_alert scheduled__2024-05-31T19:00:00+00:00 [queued]>
[2024-06-01T12:54:36.926+0000] {taskinstance.py:2170} INFO - Starting attempt 2 of 2
[2024-06-01T12:54:36.972+0000] {taskinstance.py:2191} INFO - Executing <Task(PythonOperator): send_alert> on 2024-05-31 19:00:00+00:00
[2024-06-01T12:54:36.988+0000] {standard_task_runner.py:60} INFO - Started process 2693 to run task
[2024-06-01T12:54:36.997+0000] {standard_task_runner.py:87} INFO - Running: ['***', 'tasks', 'run', 'anomaly_detection_and_alerting', 'send_alert', 'scheduled__2024-05-31T19:00:00+00:00', '--job-id', '541', '--raw', '--subdir', 'DAGS_FOLDER/alert.py', '--cfg-path', '/tmp/tmphdd_y8rb']
[2024-06-01T12:54:37.004+0000] {standard_task_runner.py:88} INFO - Job 541: Subtask send_alert
[2024-06-01T12:54:37.182+0000] {task_command.py:423} INFO - Running <TaskInstance: anomaly_detection_and_alerting.send_alert scheduled__2024-05-31T19:00:00+00:00 [running]> on host 6204b7e2d2f9
[2024-06-01T12:54:37.595+0000] {taskinstance.py:2480} INFO - Exporting env vars: AIRFLOW_CTX_DAG_OWNER='***' AIRFLOW_CTX_DAG_ID='anomaly_detection_and_alerting' AIRFLOW_CTX_TASK_ID='send_alert' AIRFLOW_CTX_EXECUTION_DATE='2024-05-31T19:00:00+00:00' AIRFLOW_CTX_TRY_NUMBER='2' AIRFLOW_CTX_DAG_RUN_ID='scheduled__2024-05-31T19:00:00+00:00'
[2024-06-01T12:54:39.699+0000] {logging_mixin.py:188} WARNING - /home/***/.local/lib/python3.8/site-packages/***/utils/email.py:154 RemovedInAirflow3Warning: Fetching SMTP credentials from configuration variables will be deprecated in a future release. Please set credentials using a connection instead.
[2024-06-01T12:54:39.701+0000] {configuration.py:1046} WARNING - section/key [smtp/smtp_user] not found in config
[2024-06-01T12:54:39.708+0000] {email.py:270} INFO - Email alerting: attempt 1
[2024-06-01T12:54:39.717+0000] {taskinstance.py:2698} ERROR - Task failed with exception
Traceback (most recent call last):
  File "/home/airflow/.local/lib/python3.8/site-packages/airflow/models/taskinstance.py", line 433, in _execute_task
    result = execute_callable(context=context, **execute_callable_kwargs)
  File "/home/airflow/.local/lib/python3.8/site-packages/airflow/operators/python.py", line 199, in execute
    return_value = self.execute_callable()
  File "/home/airflow/.local/lib/python3.8/site-packages/airflow/operators/python.py", line 216, in execute_callable
    return self.python_callable(*self.op_args, **self.op_kwargs)
  File "/opt/airflow/dags/alert.py", line 56, in send_alert
    email_operator.execute(context=kwargs)
  File "/home/airflow/.local/lib/python3.8/site-packages/airflow/operators/email.py", line 79, in execute
    send_email(
  File "/home/airflow/.local/lib/python3.8/site-packages/airflow/utils/email.py", line 80, in send_email
    return backend(
  File "/home/airflow/.local/lib/python3.8/site-packages/airflow/utils/email.py", line 154, in send_email_smtp
    send_mime_email(e_from=mail_from, e_to=recipients, mime_msg=msg, conn_id=conn_id, dryrun=dryrun)
  File "/home/airflow/.local/lib/python3.8/site-packages/airflow/utils/email.py", line 272, in send_mime_email
    smtp_conn = _get_smtp_connection(smtp_host, smtp_port, smtp_timeout, smtp_ssl)
  File "/home/airflow/.local/lib/python3.8/site-packages/airflow/utils/email.py", line 316, in _get_smtp_connection
    return smtplib.SMTP(host=host, port=port, timeout=timeout)
  File "/usr/local/lib/python3.8/smtplib.py", line 255, in __init__
    (code, msg) = self.connect(host, port)
  File "/usr/local/lib/python3.8/smtplib.py", line 339, in connect
    self.sock = self._get_socket(host, port, self.timeout)
  File "/usr/local/lib/python3.8/smtplib.py", line 310, in _get_socket
    return socket.create_connection((host, port), timeout,
  File "/usr/local/lib/python3.8/socket.py", line 808, in create_connection
    raise err
  File "/usr/local/lib/python3.8/socket.py", line 796, in create_connection
    sock.connect(sa)
ConnectionRefusedError: [Errno 111] Connection refused
[2024-06-01T12:54:39.763+0000] {taskinstance.py:1138} INFO - Marking task as FAILED. dag_id=anomaly_detection_and_alerting, task_id=send_alert, execution_date=20240531T190000, start_date=20240601T125436, end_date=20240601T125439
[2024-06-01T12:54:40.236+0000] {standard_task_runner.py:107} ERROR - Failed to execute job 541 for task send_alert ([Errno 111] Connection refused; 2693)
[2024-06-01T12:54:40.351+0000] {local_task_job_runner.py:234} INFO - Task exited with return code 1
[2024-06-01T12:54:41.044+0000] {taskinstance.py:3280} INFO - 0 downstream tasks scheduled from follow-on schedule check
