[2024-05-29T15:20:07.135+0000] {taskinstance.py:1956} INFO - Dependencies all met for dep_context=non-requeueable deps ti=<TaskInstance: trigger_dbt.dbt_run manual__2024-05-29T15:19:52.563865+00:00 [queued]>
[2024-05-29T15:20:07.195+0000] {taskinstance.py:1956} INFO - Dependencies all met for dep_context=requeueable deps ti=<TaskInstance: trigger_dbt.dbt_run manual__2024-05-29T15:19:52.563865+00:00 [queued]>
[2024-05-29T15:20:07.198+0000] {taskinstance.py:2170} INFO - Starting attempt 1 of 1
[2024-05-29T15:20:07.331+0000] {taskinstance.py:2191} INFO - Executing <Task(PythonOperator): dbt_run> on 2024-05-29 15:19:52.563865+00:00
[2024-05-29T15:20:07.364+0000] {standard_task_runner.py:60} INFO - Started process 14505 to run task
[2024-05-29T15:20:07.375+0000] {standard_task_runner.py:87} INFO - Running: ['***', 'tasks', 'run', 'trigger_dbt', 'dbt_run', 'manual__2024-05-29T15:19:52.563865+00:00', '--job-id', '380', '--raw', '--subdir', 'DAGS_FOLDER/trigger_dbt.py', '--cfg-path', '/tmp/tmp8441qaj8']
[2024-05-29T15:20:07.384+0000] {standard_task_runner.py:88} INFO - Job 380: Subtask dbt_run
[2024-05-29T15:20:07.665+0000] {task_command.py:423} INFO - Running <TaskInstance: trigger_dbt.dbt_run manual__2024-05-29T15:19:52.563865+00:00 [running]> on host be0574dd2df3
[2024-05-29T15:20:08.012+0000] {taskinstance.py:2480} INFO - Exporting env vars: AIRFLOW_CTX_DAG_OWNER='***' AIRFLOW_CTX_DAG_ID='trigger_dbt' AIRFLOW_CTX_TASK_ID='dbt_run' AIRFLOW_CTX_EXECUTION_DATE='2024-05-29T15:19:52.563865+00:00' AIRFLOW_CTX_TRY_NUMBER='1' AIRFLOW_CTX_DAG_RUN_ID='manual__2024-05-29T15:19:52.563865+00:00'
[2024-05-29T15:20:08.029+0000] {taskinstance.py:2698} ERROR - Task failed with exception
Traceback (most recent call last):
  File "/home/airflow/.local/lib/python3.8/site-packages/airflow/models/taskinstance.py", line 433, in _execute_task
    result = execute_callable(context=context, **execute_callable_kwargs)
  File "/home/airflow/.local/lib/python3.8/site-packages/airflow/operators/python.py", line 199, in execute
    return_value = self.execute_callable()
  File "/home/airflow/.local/lib/python3.8/site-packages/airflow/operators/python.py", line 216, in execute_callable
    return self.python_callable(*self.op_args, **self.op_kwargs)
  File "/opt/airflow/dags/trigger_dbt.py", line 16, in run_dbt
    os.chdir(DBT_PROJECT_PATH)
FileNotFoundError: [Errno 2] No such file or directory: 'C:\\learn-dbt\\learndbt'
[2024-05-29T15:20:08.086+0000] {taskinstance.py:1138} INFO - Marking task as FAILED. dag_id=trigger_dbt, task_id=dbt_run, execution_date=20240529T151952, start_date=20240529T152007, end_date=20240529T152008
[2024-05-29T15:20:08.191+0000] {standard_task_runner.py:107} ERROR - Failed to execute job 380 for task dbt_run ([Errno 2] No such file or directory: 'C:\\learn-dbt\\learndbt'; 14505)
[2024-05-29T15:20:08.323+0000] {local_task_job_runner.py:234} INFO - Task exited with return code 1
[2024-05-29T15:20:08.420+0000] {taskinstance.py:3280} INFO - 0 downstream tasks scheduled from follow-on schedule check
