[2024-06-04T08:19:58.821+0000] {taskinstance.py:1956} INFO - Dependencies all met for dep_context=non-requeueable deps ti=<TaskInstance: alert_combine.detect_and_alert scheduled__2024-06-03T04:00:00+00:00 [queued]>
[2024-06-04T08:19:58.878+0000] {taskinstance.py:1956} INFO - Dependencies all met for dep_context=requeueable deps ti=<TaskInstance: alert_combine.detect_and_alert scheduled__2024-06-03T04:00:00+00:00 [queued]>
[2024-06-04T08:19:58.884+0000] {taskinstance.py:2170} INFO - Starting attempt 2 of 2
[2024-06-04T08:19:59.016+0000] {taskinstance.py:2191} INFO - Executing <Task(PythonOperator): detect_and_alert> on 2024-06-03 04:00:00+00:00
[2024-06-04T08:19:59.106+0000] {standard_task_runner.py:60} INFO - Started process 28983 to run task
[2024-06-04T08:19:59.139+0000] {standard_task_runner.py:87} INFO - Running: ['***', 'tasks', 'run', 'alert_combine', 'detect_and_alert', 'scheduled__2024-06-03T04:00:00+00:00', '--job-id', '996', '--raw', '--subdir', 'DAGS_FOLDER/alert_combine.py', '--cfg-path', '/tmp/tmp5k41hma5']
[2024-06-04T08:19:59.170+0000] {standard_task_runner.py:88} INFO - Job 996: Subtask detect_and_alert
[2024-06-04T08:20:01.858+0000] {task_command.py:423} INFO - Running <TaskInstance: alert_combine.detect_and_alert scheduled__2024-06-03T04:00:00+00:00 [running]> on host e8d24771e2f4
[2024-06-04T08:20:02.533+0000] {taskinstance.py:2480} INFO - Exporting env vars: AIRFLOW_CTX_DAG_OWNER='***' AIRFLOW_CTX_DAG_ID='alert_combine' AIRFLOW_CTX_TASK_ID='detect_and_alert' AIRFLOW_CTX_EXECUTION_DATE='2024-06-03T04:00:00+00:00' AIRFLOW_CTX_TRY_NUMBER='2' AIRFLOW_CTX_DAG_RUN_ID='scheduled__2024-06-03T04:00:00+00:00'
[2024-06-04T08:20:02.796+0000] {taskinstance.py:2698} ERROR - Task failed with exception
Traceback (most recent call last):
  File "/home/airflow/.local/lib/python3.8/site-packages/airflow/models/taskinstance.py", line 433, in _execute_task
    result = execute_callable(context=context, **execute_callable_kwargs)
  File "/home/airflow/.local/lib/python3.8/site-packages/airflow/operators/python.py", line 199, in execute
    return_value = self.execute_callable()
  File "/home/airflow/.local/lib/python3.8/site-packages/airflow/operators/python.py", line 216, in execute_callable
    return self.python_callable(*self.op_args, **self.op_kwargs)
  File "/opt/airflow/dags/alert_combine.py", line 23, in anomaly_check
    model = joblib.load('/opt/airflow/dags/network_model/isolation_forest_model.pkl')
  File "/home/airflow/.local/lib/python3.8/site-packages/joblib/numpy_pickle.py", line 658, in load
    obj = _unpickle(fobj, filename, mmap_mode)
  File "/home/airflow/.local/lib/python3.8/site-packages/joblib/numpy_pickle.py", line 577, in _unpickle
    obj = unpickler.load()
  File "/usr/local/lib/python3.8/pickle.py", line 1212, in load
    dispatch[key[0]](self)
  File "/usr/local/lib/python3.8/pickle.py", line 1537, in load_stack_global
    self.append(self.find_class(module, name))
  File "/usr/local/lib/python3.8/pickle.py", line 1579, in find_class
    __import__(module, level=0)
ModuleNotFoundError: No module named 'sklearn'
[2024-06-04T08:20:02.996+0000] {taskinstance.py:1138} INFO - Marking task as FAILED. dag_id=alert_combine, task_id=detect_and_alert, execution_date=20240603T040000, start_date=20240604T081958, end_date=20240604T082002
[2024-06-04T08:20:03.152+0000] {standard_task_runner.py:107} ERROR - Failed to execute job 996 for task detect_and_alert (No module named 'sklearn'; 28983)
[2024-06-04T08:20:03.258+0000] {local_task_job_runner.py:234} INFO - Task exited with return code 1
[2024-06-04T08:20:04.428+0000] {taskinstance.py:3280} INFO - 0 downstream tasks scheduled from follow-on schedule check
