[2024-06-01T13:49:12.997+0000] {taskinstance.py:1956} INFO - Dependencies all met for dep_context=non-requeueable deps ti=<TaskInstance: anomaly_detection_and_alerting.send_alert manual__2024-06-01T13:43:54.874994+00:00 [queued]>
[2024-06-01T13:49:13.023+0000] {taskinstance.py:1956} INFO - Dependencies all met for dep_context=requeueable deps ti=<TaskInstance: anomaly_detection_and_alerting.send_alert manual__2024-06-01T13:43:54.874994+00:00 [queued]>
[2024-06-01T13:49:13.024+0000] {taskinstance.py:2170} INFO - Starting attempt 2 of 2
[2024-06-01T13:49:13.075+0000] {taskinstance.py:2191} INFO - Executing <Task(PythonOperator): send_alert> on 2024-06-01 13:43:54.874994+00:00
[2024-06-01T13:49:13.089+0000] {standard_task_runner.py:60} INFO - Started process 10936 to run task
[2024-06-01T13:49:13.097+0000] {standard_task_runner.py:87} INFO - Running: ['***', 'tasks', 'run', 'anomaly_detection_and_alerting', 'send_alert', 'manual__2024-06-01T13:43:54.874994+00:00', '--job-id', '575', '--raw', '--subdir', 'DAGS_FOLDER/alert.py', '--cfg-path', '/tmp/tmpg4o81vlj']
[2024-06-01T13:49:13.109+0000] {standard_task_runner.py:88} INFO - Job 575: Subtask send_alert
[2024-06-01T13:49:13.247+0000] {task_command.py:423} INFO - Running <TaskInstance: anomaly_detection_and_alerting.send_alert manual__2024-06-01T13:43:54.874994+00:00 [running]> on host 6204b7e2d2f9
[2024-06-01T13:49:13.569+0000] {taskinstance.py:2480} INFO - Exporting env vars: AIRFLOW_CTX_DAG_OWNER='***' AIRFLOW_CTX_DAG_ID='anomaly_detection_and_alerting' AIRFLOW_CTX_TASK_ID='send_alert' AIRFLOW_CTX_EXECUTION_DATE='2024-06-01T13:43:54.874994+00:00' AIRFLOW_CTX_TRY_NUMBER='2' AIRFLOW_CTX_DAG_RUN_ID='manual__2024-06-01T13:43:54.874994+00:00'
[2024-06-01T13:49:13.654+0000] {taskinstance.py:2698} ERROR - Task failed with exception
Traceback (most recent call last):
  File "/home/airflow/.local/lib/python3.8/site-packages/airflow/models/taskinstance.py", line 433, in _execute_task
    result = execute_callable(context=context, **execute_callable_kwargs)
  File "/home/airflow/.local/lib/python3.8/site-packages/airflow/operators/python.py", line 199, in execute
    return_value = self.execute_callable()
  File "/home/airflow/.local/lib/python3.8/site-packages/airflow/operators/python.py", line 216, in execute_callable
    return self.python_callable(*self.op_args, **self.op_kwargs)
  File "/opt/airflow/dags/alert.py", line 45, in send_alert
    with open('/opt/airflow/dags/playground/model/detected_anomalies.csv', 'r') as f:
FileNotFoundError: [Errno 2] No such file or directory: '/opt/airflow/dags/playground/model/detected_anomalies.csv'
[2024-06-01T13:49:13.720+0000] {taskinstance.py:1138} INFO - Marking task as FAILED. dag_id=anomaly_detection_and_alerting, task_id=send_alert, execution_date=20240601T134354, start_date=20240601T134913, end_date=20240601T134913
[2024-06-01T13:49:13.799+0000] {standard_task_runner.py:107} ERROR - Failed to execute job 575 for task send_alert ([Errno 2] No such file or directory: '/opt/airflow/dags/playground/model/detected_anomalies.csv'; 10936)
[2024-06-01T13:49:13.847+0000] {local_task_job_runner.py:234} INFO - Task exited with return code 1
[2024-06-01T13:49:13.949+0000] {taskinstance.py:3280} INFO - 0 downstream tasks scheduled from follow-on schedule check
