[2024-05-30T01:48:12.331+0000] {taskinstance.py:1956} INFO - Dependencies all met for dep_context=non-requeueable deps ti=<TaskInstance: dbt.dbt_run manual__2024-05-30T01:48:09.445749+00:00 [queued]>
[2024-05-30T01:48:12.348+0000] {taskinstance.py:1956} INFO - Dependencies all met for dep_context=requeueable deps ti=<TaskInstance: dbt.dbt_run manual__2024-05-30T01:48:09.445749+00:00 [queued]>
[2024-05-30T01:48:12.349+0000] {taskinstance.py:2170} INFO - Starting attempt 1 of 1
[2024-05-30T01:48:12.381+0000] {taskinstance.py:2191} INFO - Executing <Task(PythonOperator): dbt_run> on 2024-05-30 01:48:09.445749+00:00
[2024-05-30T01:48:12.392+0000] {standard_task_runner.py:60} INFO - Started process 7542 to run task
[2024-05-30T01:48:12.397+0000] {standard_task_runner.py:87} INFO - Running: ['***', 'tasks', 'run', 'dbt', 'dbt_run', 'manual__2024-05-30T01:48:09.445749+00:00', '--job-id', '395', '--raw', '--subdir', 'DAGS_FOLDER/dbt.py', '--cfg-path', '/tmp/tmpzl5bow5k']
[2024-05-30T01:48:12.402+0000] {standard_task_runner.py:88} INFO - Job 395: Subtask dbt_run
[2024-05-30T01:48:12.487+0000] {task_command.py:423} INFO - Running <TaskInstance: dbt.dbt_run manual__2024-05-30T01:48:09.445749+00:00 [running]> on host dd00f1ab2b6c
[2024-05-30T01:48:12.610+0000] {taskinstance.py:2480} INFO - Exporting env vars: AIRFLOW_CTX_DAG_OWNER='***' AIRFLOW_CTX_DAG_ID='dbt' AIRFLOW_CTX_TASK_ID='dbt_run' AIRFLOW_CTX_EXECUTION_DATE='2024-05-30T01:48:09.445749+00:00' AIRFLOW_CTX_TRY_NUMBER='1' AIRFLOW_CTX_DAG_RUN_ID='manual__2024-05-30T01:48:09.445749+00:00'
[2024-05-30T01:48:12.628+0000] {taskinstance.py:2698} ERROR - Task failed with exception
Traceback (most recent call last):
  File "/home/airflow/.local/lib/python3.8/site-packages/airflow/models/taskinstance.py", line 433, in _execute_task
    result = execute_callable(context=context, **execute_callable_kwargs)
  File "/home/airflow/.local/lib/python3.8/site-packages/airflow/operators/python.py", line 199, in execute
    return_value = self.execute_callable()
  File "/home/airflow/.local/lib/python3.8/site-packages/airflow/operators/python.py", line 216, in execute_callable
    return self.python_callable(*self.op_args, **self.op_kwargs)
  File "/opt/airflow/dags/dbt.py", line 24, in run_dbt
    subprocess.run(["dbt", "run", "--select", "clean_network"], check=True, cwd=DBT_PROJECT_PATH)
  File "/usr/local/lib/python3.8/subprocess.py", line 493, in run
    with Popen(*popenargs, **kwargs) as process:
  File "/usr/local/lib/python3.8/subprocess.py", line 858, in __init__
    self._execute_child(args, executable, preexec_fn, close_fds,
  File "/usr/local/lib/python3.8/subprocess.py", line 1720, in _execute_child
    raise child_exception_type(errno_num, err_msg, err_filename)
FileNotFoundError: [Errno 2] No such file or directory: 'C:\x07irflow\\dags\\dbt\network'
[2024-05-30T01:48:12.648+0000] {taskinstance.py:1138} INFO - Marking task as FAILED. dag_id=dbt, task_id=dbt_run, execution_date=20240530T014809, start_date=20240530T014812, end_date=20240530T014812
[2024-05-30T01:48:12.670+0000] {standard_task_runner.py:107} ERROR - Failed to execute job 395 for task dbt_run ([Errno 2] No such file or directory: 'C:\x07irflow\\dags\\dbt\network'; 7542)
[2024-05-30T01:48:12.692+0000] {local_task_job_runner.py:234} INFO - Task exited with return code 1
[2024-05-30T01:48:12.722+0000] {taskinstance.py:3280} INFO - 0 downstream tasks scheduled from follow-on schedule check
