[2024-05-29T14:05:59.424+0000] {taskinstance.py:1956} INFO - Dependencies all met for dep_context=non-requeueable deps ti=<TaskInstance: dbt_test.run_dbt_model manual__2024-05-29T14:00:54.551600+00:00 [queued]>
[2024-05-29T14:05:59.541+0000] {taskinstance.py:1956} INFO - Dependencies all met for dep_context=requeueable deps ti=<TaskInstance: dbt_test.run_dbt_model manual__2024-05-29T14:00:54.551600+00:00 [queued]>
[2024-05-29T14:05:59.550+0000] {taskinstance.py:2170} INFO - Starting attempt 2 of 2
[2024-05-29T14:05:59.727+0000] {taskinstance.py:2191} INFO - Executing <Task(BashOperator): run_dbt_model> on 2024-05-29 14:00:54.551600+00:00
[2024-05-29T14:05:59.784+0000] {standard_task_runner.py:60} INFO - Started process 4825 to run task
[2024-05-29T14:05:59.798+0000] {standard_task_runner.py:87} INFO - Running: ['***', 'tasks', 'run', 'dbt_test', 'run_dbt_model', 'manual__2024-05-29T14:00:54.551600+00:00', '--job-id', '362', '--raw', '--subdir', 'DAGS_FOLDER/dbt_test.py', '--cfg-path', '/tmp/tmp_cmx_5pf']
[2024-05-29T14:05:59.823+0000] {standard_task_runner.py:88} INFO - Job 362: Subtask run_dbt_model
[2024-05-29T14:06:00.195+0000] {task_command.py:423} INFO - Running <TaskInstance: dbt_test.run_dbt_model manual__2024-05-29T14:00:54.551600+00:00 [running]> on host be0574dd2df3
[2024-05-29T14:06:00.689+0000] {taskinstance.py:2480} INFO - Exporting env vars: AIRFLOW_CTX_DAG_OWNER='***' AIRFLOW_CTX_DAG_ID='dbt_test' AIRFLOW_CTX_TASK_ID='run_dbt_model' AIRFLOW_CTX_EXECUTION_DATE='2024-05-29T14:00:54.551600+00:00' AIRFLOW_CTX_TRY_NUMBER='2' AIRFLOW_CTX_DAG_RUN_ID='manual__2024-05-29T14:00:54.551600+00:00'
[2024-05-29T14:06:00.703+0000] {subprocess.py:63} INFO - Tmp dir root location: /tmp
[2024-05-29T14:06:00.709+0000] {subprocess.py:75} INFO - Running command: ['/usr/bin/bash', '-c', 'cd C:\\learn-dbt\\learndbt\\models  && dbt run --models clean_network']
[2024-05-29T14:06:00.752+0000] {subprocess.py:86} INFO - Output:
[2024-05-29T14:06:00.784+0000] {subprocess.py:93} INFO - /usr/bin/bash: line 1: cd: C:learn-dbtlearndbtmodels: No such file or directory
[2024-05-29T14:06:00.788+0000] {subprocess.py:97} INFO - Command exited with return code 1
[2024-05-29T14:06:00.817+0000] {taskinstance.py:2698} ERROR - Task failed with exception
Traceback (most recent call last):
  File "/home/airflow/.local/lib/python3.8/site-packages/airflow/models/taskinstance.py", line 433, in _execute_task
    result = execute_callable(context=context, **execute_callable_kwargs)
  File "/home/airflow/.local/lib/python3.8/site-packages/airflow/operators/bash.py", line 212, in execute
    raise AirflowException(
airflow.exceptions.AirflowException: Bash command failed. The command returned a non-zero exit code 1.
[2024-05-29T14:06:00.829+0000] {taskinstance.py:1138} INFO - Marking task as FAILED. dag_id=dbt_test, task_id=run_dbt_model, execution_date=20240529T140054, start_date=20240529T140559, end_date=20240529T140600
[2024-05-29T14:06:00.866+0000] {standard_task_runner.py:107} ERROR - Failed to execute job 362 for task run_dbt_model (Bash command failed. The command returned a non-zero exit code 1.; 4825)
[2024-05-29T14:06:00.914+0000] {local_task_job_runner.py:234} INFO - Task exited with return code 1
[2024-05-29T14:06:00.984+0000] {taskinstance.py:3280} INFO - 0 downstream tasks scheduled from follow-on schedule check
