[2024-05-30T07:58:02.191+0000] {taskinstance.py:1956} INFO - Dependencies all met for dep_context=non-requeueable deps ti=<TaskInstance: dbt.dbt_run manual__2024-05-30T01:11:10.787524+00:00 [queued]>
[2024-05-30T07:58:02.240+0000] {taskinstance.py:1956} INFO - Dependencies all met for dep_context=requeueable deps ti=<TaskInstance: dbt.dbt_run manual__2024-05-30T01:11:10.787524+00:00 [queued]>
[2024-05-30T07:58:02.241+0000] {taskinstance.py:2170} INFO - Starting attempt 2 of 3
[2024-05-30T07:58:02.278+0000] {taskinstance.py:2191} INFO - Executing <Task(PythonOperator): dbt_run> on 2024-05-30 01:11:10.787524+00:00
[2024-05-30T07:58:02.290+0000] {standard_task_runner.py:60} INFO - Started process 53917 to run task
[2024-05-30T07:58:02.294+0000] {standard_task_runner.py:87} INFO - Running: ['***', 'tasks', 'run', 'dbt', 'dbt_run', 'manual__2024-05-30T01:11:10.787524+00:00', '--job-id', '417', '--raw', '--subdir', 'DAGS_FOLDER/dbt.py', '--cfg-path', '/tmp/tmpb2o31n55']
[2024-05-30T07:58:02.297+0000] {standard_task_runner.py:88} INFO - Job 417: Subtask dbt_run
[2024-05-30T07:58:02.396+0000] {task_command.py:423} INFO - Running <TaskInstance: dbt.dbt_run manual__2024-05-30T01:11:10.787524+00:00 [running]> on host dd00f1ab2b6c
[2024-05-30T07:58:02.608+0000] {taskinstance.py:2480} INFO - Exporting env vars: AIRFLOW_CTX_DAG_OWNER='***' AIRFLOW_CTX_DAG_ID='dbt' AIRFLOW_CTX_TASK_ID='dbt_run' AIRFLOW_CTX_EXECUTION_DATE='2024-05-30T01:11:10.787524+00:00' AIRFLOW_CTX_TRY_NUMBER='2' AIRFLOW_CTX_DAG_RUN_ID='manual__2024-05-30T01:11:10.787524+00:00'
[2024-05-30T07:58:02.657+0000] {taskinstance.py:2698} ERROR - Task failed with exception
Traceback (most recent call last):
  File "/home/airflow/.local/lib/python3.8/site-packages/airflow/models/taskinstance.py", line 433, in _execute_task
    result = execute_callable(context=context, **execute_callable_kwargs)
  File "/home/airflow/.local/lib/python3.8/site-packages/airflow/operators/python.py", line 199, in execute
    return_value = self.execute_callable()
  File "/home/airflow/.local/lib/python3.8/site-packages/airflow/operators/python.py", line 216, in execute_callable
    return self.python_callable(*self.op_args, **self.op_kwargs)
  File "/opt/airflow/dags/dbt.py", line 7, in run_dbt
    subprocess.run(["dbt.exe", "cd", "C:\\airflow\\dbt\\network;", "dbt", "run"])
  File "/usr/local/lib/python3.8/subprocess.py", line 493, in run
    with Popen(*popenargs, **kwargs) as process:
  File "/usr/local/lib/python3.8/subprocess.py", line 858, in __init__
    self._execute_child(args, executable, preexec_fn, close_fds,
  File "/usr/local/lib/python3.8/subprocess.py", line 1720, in _execute_child
    raise child_exception_type(errno_num, err_msg, err_filename)
PermissionError: [Errno 13] Permission denied: 'dbt.exe'
[2024-05-30T07:58:02.701+0000] {taskinstance.py:1138} INFO - Marking task as UP_FOR_RETRY. dag_id=dbt, task_id=dbt_run, execution_date=20240530T011110, start_date=20240530T075802, end_date=20240530T075802
[2024-05-30T07:58:02.742+0000] {standard_task_runner.py:107} ERROR - Failed to execute job 417 for task dbt_run ([Errno 13] Permission denied: 'dbt.exe'; 53917)
[2024-05-30T07:58:02.800+0000] {local_task_job_runner.py:234} INFO - Task exited with return code 1
[2024-05-30T07:58:02.850+0000] {taskinstance.py:3280} INFO - 0 downstream tasks scheduled from follow-on schedule check
