[2024-06-07T09:51:48.371+0000] {taskinstance.py:1956} INFO - Dependencies all met for dep_context=non-requeueable deps ti=<TaskInstance: csv_to_bigquery_2.run_transform_script manual__2024-06-07T09:50:11.395682+00:00 [queued]>
[2024-06-07T09:51:48.410+0000] {taskinstance.py:1956} INFO - Dependencies all met for dep_context=requeueable deps ti=<TaskInstance: csv_to_bigquery_2.run_transform_script manual__2024-06-07T09:50:11.395682+00:00 [queued]>
[2024-06-07T09:51:48.412+0000] {taskinstance.py:2170} INFO - Starting attempt 1 of 2
[2024-06-07T09:51:48.491+0000] {taskinstance.py:2191} INFO - Executing <Task(PythonOperator): run_transform_script> on 2024-06-07 09:50:11.395682+00:00
[2024-06-07T09:51:48.521+0000] {standard_task_runner.py:60} INFO - Started process 71651 to run task
[2024-06-07T09:51:48.529+0000] {standard_task_runner.py:87} INFO - Running: ['***', 'tasks', 'run', 'csv_to_bigquery_2', 'run_transform_script', 'manual__2024-06-07T09:50:11.395682+00:00', '--job-id', '1358', '--raw', '--subdir', 'DAGS_FOLDER/csv_to_bigquery_2.py', '--cfg-path', '/tmp/tmpghdd97ni']
[2024-06-07T09:51:48.541+0000] {standard_task_runner.py:88} INFO - Job 1358: Subtask run_transform_script
[2024-06-07T09:51:48.723+0000] {task_command.py:423} INFO - Running <TaskInstance: csv_to_bigquery_2.run_transform_script manual__2024-06-07T09:50:11.395682+00:00 [running]> on host e396011bc044
[2024-06-07T09:51:48.970+0000] {taskinstance.py:2480} INFO - Exporting env vars: AIRFLOW_CTX_DAG_OWNER='***' AIRFLOW_CTX_DAG_ID='csv_to_bigquery_2' AIRFLOW_CTX_TASK_ID='run_transform_script' AIRFLOW_CTX_EXECUTION_DATE='2024-06-07T09:50:11.395682+00:00' AIRFLOW_CTX_TRY_NUMBER='1' AIRFLOW_CTX_DAG_RUN_ID='manual__2024-06-07T09:50:11.395682+00:00'
[2024-06-07T09:52:20.703+0000] {logging_mixin.py:188} INFO - Traceback (most recent call last):
  File "/home/***/.local/lib/python3.8/site-packages/pandas/core/indexes/base.py", line 3653, in get_loc
    return self._engine.get_loc(casted_key)
  File "pandas/_libs/index.pyx", line 147, in pandas._libs.index.IndexEngine.get_loc
  File "pandas/_libs/index.pyx", line 176, in pandas._libs.index.IndexEngine.get_loc
  File "pandas/_libs/hashtable_class_helper.pxi", line 7080, in pandas._libs.hashtable.PyObjectHashTable.get_item
  File "pandas/_libs/hashtable_class_helper.pxi", line 7088, in pandas._libs.hashtable.PyObjectHashTable.get_item
KeyError: 'protocol'

The above exception was the direct cause of the following exception:

Traceback (most recent call last):
  File "/opt/***/dags/network_model/dataprep.py", line 103, in <module>
    main()
  File "/opt/***/dags/network_model/dataprep.py", line 86, in main
    transformed_data = transform_data_with_label_encoder(data, columns_to_transform)
  File "/opt/***/dags/network_model/dataprep.py", line 30, in transform_data_with_label_encoder
    data[col] = le.fit_transform(data[col])
  File "/home/***/.local/lib/python3.8/site-packages/pandas/core/frame.py", line 3761, in __getitem__
    indexer = self.columns.get_loc(key)
  File "/home/***/.local/lib/python3.8/site-packages/pandas/core/indexes/base.py", line 3655, in get_loc
    raise KeyError(key) from err
KeyError: 'protocol'
[2024-06-07T09:52:20.708+0000] {taskinstance.py:2698} ERROR - Task failed with exception
Traceback (most recent call last):
  File "/home/airflow/.local/lib/python3.8/site-packages/airflow/models/taskinstance.py", line 433, in _execute_task
    result = execute_callable(context=context, **execute_callable_kwargs)
  File "/home/airflow/.local/lib/python3.8/site-packages/airflow/operators/python.py", line 199, in execute
    return_value = self.execute_callable()
  File "/home/airflow/.local/lib/python3.8/site-packages/airflow/operators/python.py", line 216, in execute_callable
    return self.python_callable(*self.op_args, **self.op_kwargs)
  File "/opt/airflow/dags/csv_to_bigquery_2.py", line 87, in run_transform_script
    raise Exception("Script failed: " + result.stderr)
Exception: Script failed: Traceback (most recent call last):
  File "/home/***/.local/lib/python3.8/site-packages/pandas/core/indexes/base.py", line 3653, in get_loc
    return self._engine.get_loc(casted_key)
  File "pandas/_libs/index.pyx", line 147, in pandas._libs.index.IndexEngine.get_loc
  File "pandas/_libs/index.pyx", line 176, in pandas._libs.index.IndexEngine.get_loc
  File "pandas/_libs/hashtable_class_helper.pxi", line 7080, in pandas._libs.hashtable.PyObjectHashTable.get_item
  File "pandas/_libs/hashtable_class_helper.pxi", line 7088, in pandas._libs.hashtable.PyObjectHashTable.get_item
KeyError: 'protocol'

The above exception was the direct cause of the following exception:

Traceback (most recent call last):
  File "/opt/***/dags/network_model/dataprep.py", line 103, in <module>
    main()
  File "/opt/***/dags/network_model/dataprep.py", line 86, in main
    transformed_data = transform_data_with_label_encoder(data, columns_to_transform)
  File "/opt/***/dags/network_model/dataprep.py", line 30, in transform_data_with_label_encoder
    data[col] = le.fit_transform(data[col])
  File "/home/***/.local/lib/python3.8/site-packages/pandas/core/frame.py", line 3761, in __getitem__
    indexer = self.columns.get_loc(key)
  File "/home/***/.local/lib/python3.8/site-packages/pandas/core/indexes/base.py", line 3655, in get_loc
    raise KeyError(key) from err
KeyError: 'protocol'

[2024-06-07T09:52:20.751+0000] {taskinstance.py:1138} INFO - Marking task as UP_FOR_RETRY. dag_id=csv_to_bigquery_2, task_id=run_transform_script, execution_date=20240607T095011, start_date=20240607T095148, end_date=20240607T095220
[2024-06-07T09:52:20.819+0000] {standard_task_runner.py:107} ERROR - Failed to execute job 1358 for task run_transform_script (Script failed: Traceback (most recent call last):
  File "/home/***/.local/lib/python3.8/site-packages/pandas/core/indexes/base.py", line 3653, in get_loc
    return self._engine.get_loc(casted_key)
  File "pandas/_libs/index.pyx", line 147, in pandas._libs.index.IndexEngine.get_loc
  File "pandas/_libs/index.pyx", line 176, in pandas._libs.index.IndexEngine.get_loc
  File "pandas/_libs/hashtable_class_helper.pxi", line 7080, in pandas._libs.hashtable.PyObjectHashTable.get_item
  File "pandas/_libs/hashtable_class_helper.pxi", line 7088, in pandas._libs.hashtable.PyObjectHashTable.get_item
KeyError: 'protocol'

The above exception was the direct cause of the following exception:

Traceback (most recent call last):
  File "/opt/***/dags/network_model/dataprep.py", line 103, in <module>
    main()
  File "/opt/***/dags/network_model/dataprep.py", line 86, in main
    transformed_data = transform_data_with_label_encoder(data, columns_to_transform)
  File "/opt/***/dags/network_model/dataprep.py", line 30, in transform_data_with_label_encoder
    data[col] = le.fit_transform(data[col])
  File "/home/***/.local/lib/python3.8/site-packages/pandas/core/frame.py", line 3761, in __getitem__
    indexer = self.columns.get_loc(key)
  File "/home/***/.local/lib/python3.8/site-packages/pandas/core/indexes/base.py", line 3655, in get_loc
    raise KeyError(key) from err
KeyError: 'protocol'
; 71651)
[2024-06-07T09:52:20.872+0000] {local_task_job_runner.py:234} INFO - Task exited with return code 1
[2024-06-07T09:52:20.927+0000] {taskinstance.py:3280} INFO - 0 downstream tasks scheduled from follow-on schedule check
