[2024-06-07T07:11:16.753+0000] {taskinstance.py:1956} INFO - Dependencies all met for dep_context=non-requeueable deps ti=<TaskInstance: csv_to_bigquery_2.run_transform_script manual__2024-06-07T07:09:48.303368+00:00 [queued]>
[2024-06-07T07:11:16.785+0000] {taskinstance.py:1956} INFO - Dependencies all met for dep_context=requeueable deps ti=<TaskInstance: csv_to_bigquery_2.run_transform_script manual__2024-06-07T07:09:48.303368+00:00 [queued]>
[2024-06-07T07:11:16.786+0000] {taskinstance.py:2170} INFO - Starting attempt 1 of 2
[2024-06-07T07:11:16.819+0000] {taskinstance.py:2191} INFO - Executing <Task(PythonOperator): run_transform_script> on 2024-06-07 07:09:48.303368+00:00
[2024-06-07T07:11:16.836+0000] {standard_task_runner.py:60} INFO - Started process 22938 to run task
[2024-06-07T07:11:16.842+0000] {standard_task_runner.py:87} INFO - Running: ['***', 'tasks', 'run', 'csv_to_bigquery_2', 'run_transform_script', 'manual__2024-06-07T07:09:48.303368+00:00', '--job-id', '1317', '--raw', '--subdir', 'DAGS_FOLDER/csv_to_bigquery_2.py', '--cfg-path', '/tmp/tmpu0znbaya']
[2024-06-07T07:11:16.846+0000] {standard_task_runner.py:88} INFO - Job 1317: Subtask run_transform_script
[2024-06-07T07:11:16.980+0000] {task_command.py:423} INFO - Running <TaskInstance: csv_to_bigquery_2.run_transform_script manual__2024-06-07T07:09:48.303368+00:00 [running]> on host e396011bc044
[2024-06-07T07:11:17.164+0000] {taskinstance.py:2480} INFO - Exporting env vars: AIRFLOW_CTX_DAG_OWNER='***' AIRFLOW_CTX_DAG_ID='csv_to_bigquery_2' AIRFLOW_CTX_TASK_ID='run_transform_script' AIRFLOW_CTX_EXECUTION_DATE='2024-06-07T07:09:48.303368+00:00' AIRFLOW_CTX_TRY_NUMBER='1' AIRFLOW_CTX_DAG_RUN_ID='manual__2024-06-07T07:09:48.303368+00:00'
[2024-06-07T07:11:19.625+0000] {logging_mixin.py:188} INFO - Traceback (most recent call last):
  File "/opt/***/dags/network_model/dataprep.py", line 16, in <module>
    client = bigquery.Client()
  File "/home/***/.local/lib/python3.8/site-packages/google/cloud/bigquery/client.py", line 237, in __init__
    super(Client, self).__init__(
  File "/home/***/.local/lib/python3.8/site-packages/google/cloud/client/__init__.py", line 320, in __init__
    _ClientProjectMixin.__init__(self, project=project, credentials=credentials)
  File "/home/***/.local/lib/python3.8/site-packages/google/cloud/client/__init__.py", line 268, in __init__
    project = self._determine_default(project)
  File "/home/***/.local/lib/python3.8/site-packages/google/cloud/client/__init__.py", line 287, in _determine_default
    return _determine_default_project(project)
  File "/home/***/.local/lib/python3.8/site-packages/google/cloud/_helpers/__init__.py", line 152, in _determine_default_project
    _, project = google.auth.default()
  File "/home/***/.local/lib/python3.8/site-packages/google/auth/_default.py", line 657, in default
    credentials, project_id = checker()
  File "/home/***/.local/lib/python3.8/site-packages/google/auth/_default.py", line 650, in <lambda>
    lambda: _get_explicit_environ_credentials(quota_project_id=quota_project_id),
  File "/home/***/.local/lib/python3.8/site-packages/google/auth/_default.py", line 270, in _get_explicit_environ_credentials
    credentials, project_id = load_credentials_from_file(
  File "/home/***/.local/lib/python3.8/site-packages/google/auth/_default.py", line 114, in load_credentials_from_file
    raise exceptions.DefaultCredentialsError(
google.auth.exceptions.DefaultCredentialsError: File C:/***/dags/credential.json was not found.
[2024-06-07T07:11:19.626+0000] {taskinstance.py:2698} ERROR - Task failed with exception
Traceback (most recent call last):
  File "/home/airflow/.local/lib/python3.8/site-packages/airflow/models/taskinstance.py", line 433, in _execute_task
    result = execute_callable(context=context, **execute_callable_kwargs)
  File "/home/airflow/.local/lib/python3.8/site-packages/airflow/operators/python.py", line 199, in execute
    return_value = self.execute_callable()
  File "/home/airflow/.local/lib/python3.8/site-packages/airflow/operators/python.py", line 216, in execute_callable
    return self.python_callable(*self.op_args, **self.op_kwargs)
  File "/opt/airflow/dags/csv_to_bigquery_2.py", line 87, in run_transform_script
    raise Exception("Script failed: " + result.stderr)
Exception: Script failed: Traceback (most recent call last):
  File "/opt/***/dags/network_model/dataprep.py", line 16, in <module>
    client = bigquery.Client()
  File "/home/***/.local/lib/python3.8/site-packages/google/cloud/bigquery/client.py", line 237, in __init__
    super(Client, self).__init__(
  File "/home/***/.local/lib/python3.8/site-packages/google/cloud/client/__init__.py", line 320, in __init__
    _ClientProjectMixin.__init__(self, project=project, credentials=credentials)
  File "/home/***/.local/lib/python3.8/site-packages/google/cloud/client/__init__.py", line 268, in __init__
    project = self._determine_default(project)
  File "/home/***/.local/lib/python3.8/site-packages/google/cloud/client/__init__.py", line 287, in _determine_default
    return _determine_default_project(project)
  File "/home/***/.local/lib/python3.8/site-packages/google/cloud/_helpers/__init__.py", line 152, in _determine_default_project
    _, project = google.auth.default()
  File "/home/***/.local/lib/python3.8/site-packages/google/auth/_default.py", line 657, in default
    credentials, project_id = checker()
  File "/home/***/.local/lib/python3.8/site-packages/google/auth/_default.py", line 650, in <lambda>
    lambda: _get_explicit_environ_credentials(quota_project_id=quota_project_id),
  File "/home/***/.local/lib/python3.8/site-packages/google/auth/_default.py", line 270, in _get_explicit_environ_credentials
    credentials, project_id = load_credentials_from_file(
  File "/home/***/.local/lib/python3.8/site-packages/google/auth/_default.py", line 114, in load_credentials_from_file
    raise exceptions.DefaultCredentialsError(
google.auth.exceptions.DefaultCredentialsError: File C:/***/dags/credential.json was not found.

[2024-06-07T07:11:19.648+0000] {taskinstance.py:1138} INFO - Marking task as UP_FOR_RETRY. dag_id=csv_to_bigquery_2, task_id=run_transform_script, execution_date=20240607T070948, start_date=20240607T071116, end_date=20240607T071119
[2024-06-07T07:11:19.685+0000] {standard_task_runner.py:107} ERROR - Failed to execute job 1317 for task run_transform_script (Script failed: Traceback (most recent call last):
  File "/opt/***/dags/network_model/dataprep.py", line 16, in <module>
    client = bigquery.Client()
  File "/home/***/.local/lib/python3.8/site-packages/google/cloud/bigquery/client.py", line 237, in __init__
    super(Client, self).__init__(
  File "/home/***/.local/lib/python3.8/site-packages/google/cloud/client/__init__.py", line 320, in __init__
    _ClientProjectMixin.__init__(self, project=project, credentials=credentials)
  File "/home/***/.local/lib/python3.8/site-packages/google/cloud/client/__init__.py", line 268, in __init__
    project = self._determine_default(project)
  File "/home/***/.local/lib/python3.8/site-packages/google/cloud/client/__init__.py", line 287, in _determine_default
    return _determine_default_project(project)
  File "/home/***/.local/lib/python3.8/site-packages/google/cloud/_helpers/__init__.py", line 152, in _determine_default_project
    _, project = google.auth.default()
  File "/home/***/.local/lib/python3.8/site-packages/google/auth/_default.py", line 657, in default
    credentials, project_id = checker()
  File "/home/***/.local/lib/python3.8/site-packages/google/auth/_default.py", line 650, in <lambda>
    lambda: _get_explicit_environ_credentials(quota_project_id=quota_project_id),
  File "/home/***/.local/lib/python3.8/site-packages/google/auth/_default.py", line 270, in _get_explicit_environ_credentials
    credentials, project_id = load_credentials_from_file(
  File "/home/***/.local/lib/python3.8/site-packages/google/auth/_default.py", line 114, in load_credentials_from_file
    raise exceptions.DefaultCredentialsError(
google.auth.exceptions.DefaultCredentialsError: File C:/***/dags/credential.json was not found.
; 22938)
[2024-06-07T07:11:19.712+0000] {local_task_job_runner.py:234} INFO - Task exited with return code 1
[2024-06-07T07:11:19.762+0000] {taskinstance.py:3280} INFO - 0 downstream tasks scheduled from follow-on schedule check
