[2024-05-29T14:38:52.514+0000] {taskinstance.py:1956} INFO - Dependencies all met for dep_context=non-requeueable deps ti=<TaskInstance: trigger_dbt.get_path manual__2024-05-29T14:36:34.539481+00:00 [queued]>
[2024-05-29T14:38:52.582+0000] {taskinstance.py:1956} INFO - Dependencies all met for dep_context=requeueable deps ti=<TaskInstance: trigger_dbt.get_path manual__2024-05-29T14:36:34.539481+00:00 [queued]>
[2024-05-29T14:38:52.584+0000] {taskinstance.py:2170} INFO - Starting attempt 1 of 2
[2024-05-29T14:38:52.737+0000] {taskinstance.py:2191} INFO - Executing <Task(BashOperator): get_path> on 2024-05-29 14:36:34.539481+00:00
[2024-05-29T14:38:52.829+0000] {standard_task_runner.py:60} INFO - Started process 9128 to run task
[2024-05-29T14:38:52.872+0000] {standard_task_runner.py:87} INFO - Running: ['***', 'tasks', 'run', 'trigger_dbt', 'get_path', 'manual__2024-05-29T14:36:34.539481+00:00', '--job-id', '371', '--raw', '--subdir', 'DAGS_FOLDER/trigger_dbt.py', '--cfg-path', '/tmp/tmpn3au_cws']
[2024-05-29T14:38:52.893+0000] {standard_task_runner.py:88} INFO - Job 371: Subtask get_path
[2024-05-29T14:38:53.141+0000] {task_command.py:423} INFO - Running <TaskInstance: trigger_dbt.get_path manual__2024-05-29T14:36:34.539481+00:00 [running]> on host be0574dd2df3
[2024-05-29T14:38:53.724+0000] {taskinstance.py:2480} INFO - Exporting env vars: AIRFLOW_CTX_DAG_OWNER='***' AIRFLOW_CTX_DAG_ID='trigger_dbt' AIRFLOW_CTX_TASK_ID='get_path' AIRFLOW_CTX_EXECUTION_DATE='2024-05-29T14:36:34.539481+00:00' AIRFLOW_CTX_TRY_NUMBER='1' AIRFLOW_CTX_DAG_RUN_ID='manual__2024-05-29T14:36:34.539481+00:00'
[2024-05-29T14:38:53.740+0000] {subprocess.py:63} INFO - Tmp dir root location: /tmp
[2024-05-29T14:38:53.772+0000] {subprocess.py:75} INFO - Running command: ['/usr/bin/bash', '-c', 'cd C:/learn-dbt/learndbt']
[2024-05-29T14:38:53.865+0000] {subprocess.py:86} INFO - Output:
[2024-05-29T14:38:53.926+0000] {subprocess.py:93} INFO - /usr/bin/bash: line 1: cd: C:/learn-dbt/learndbt: No such file or directory
[2024-05-29T14:38:53.929+0000] {subprocess.py:97} INFO - Command exited with return code 1
[2024-05-29T14:38:53.975+0000] {taskinstance.py:2698} ERROR - Task failed with exception
Traceback (most recent call last):
  File "/home/airflow/.local/lib/python3.8/site-packages/airflow/models/taskinstance.py", line 433, in _execute_task
    result = execute_callable(context=context, **execute_callable_kwargs)
  File "/home/airflow/.local/lib/python3.8/site-packages/airflow/operators/bash.py", line 212, in execute
    raise AirflowException(
airflow.exceptions.AirflowException: Bash command failed. The command returned a non-zero exit code 1.
[2024-05-29T14:38:53.990+0000] {taskinstance.py:1138} INFO - Marking task as UP_FOR_RETRY. dag_id=trigger_dbt, task_id=get_path, execution_date=20240529T143634, start_date=20240529T143852, end_date=20240529T143853
[2024-05-29T14:38:54.065+0000] {standard_task_runner.py:107} ERROR - Failed to execute job 371 for task get_path (Bash command failed. The command returned a non-zero exit code 1.; 9128)
[2024-05-29T14:38:54.135+0000] {local_task_job_runner.py:234} INFO - Task exited with return code 1
[2024-05-29T14:38:54.279+0000] {taskinstance.py:3280} INFO - 0 downstream tasks scheduled from follow-on schedule check
