[2024-06-05T08:23:13.507+0000] {taskinstance.py:1956} INFO - Dependencies all met for dep_context=non-requeueable deps ti=<TaskInstance: bigquery_transform_python.run_transform_script manual__2024-06-05T08:18:08.591389+00:00 [queued]>
[2024-06-05T08:23:13.519+0000] {taskinstance.py:1956} INFO - Dependencies all met for dep_context=requeueable deps ti=<TaskInstance: bigquery_transform_python.run_transform_script manual__2024-06-05T08:18:08.591389+00:00 [queued]>
[2024-06-05T08:23:13.520+0000] {taskinstance.py:2170} INFO - Starting attempt 2 of 2
[2024-06-05T08:23:13.544+0000] {taskinstance.py:2191} INFO - Executing <Task(PythonOperator): run_transform_script> on 2024-06-05 08:18:08.591389+00:00
[2024-06-05T08:23:13.551+0000] {standard_task_runner.py:60} INFO - Started process 2790 to run task
[2024-06-05T08:23:13.556+0000] {standard_task_runner.py:87} INFO - Running: ['***', 'tasks', 'run', 'bigquery_transform_python', 'run_transform_script', 'manual__2024-06-05T08:18:08.591389+00:00', '--job-id', '1114', '--raw', '--subdir', 'DAGS_FOLDER/bigquery_transform_python.py', '--cfg-path', '/tmp/tmp_knsc4yo']
[2024-06-05T08:23:13.558+0000] {standard_task_runner.py:88} INFO - Job 1114: Subtask run_transform_script
[2024-06-05T08:23:13.609+0000] {task_command.py:423} INFO - Running <TaskInstance: bigquery_transform_python.run_transform_script manual__2024-06-05T08:18:08.591389+00:00 [running]> on host e98391521b34
[2024-06-05T08:23:13.695+0000] {taskinstance.py:2480} INFO - Exporting env vars: AIRFLOW_CTX_DAG_OWNER='***' AIRFLOW_CTX_DAG_ID='bigquery_transform_python' AIRFLOW_CTX_TASK_ID='run_transform_script' AIRFLOW_CTX_EXECUTION_DATE='2024-06-05T08:18:08.591389+00:00' AIRFLOW_CTX_TRY_NUMBER='2' AIRFLOW_CTX_DAG_RUN_ID='manual__2024-06-05T08:18:08.591389+00:00'
[2024-06-05T08:23:15.452+0000] {logging_mixin.py:188} INFO - Traceback (most recent call last):
  File "/opt/***/dags/network_model/dataprep.py", line 10, in <module>
    client = bigquery.Client()
  File "/home/***/.local/lib/python3.8/site-packages/google/cloud/bigquery/client.py", line 237, in __init__
    super(Client, self).__init__(
  File "/home/***/.local/lib/python3.8/site-packages/google/cloud/client/__init__.py", line 320, in __init__
    _ClientProjectMixin.__init__(self, project=project, credentials=credentials)
  File "/home/***/.local/lib/python3.8/site-packages/google/cloud/client/__init__.py", line 268, in __init__
    project = self._determine_default(project)
  File "/home/***/.local/lib/python3.8/site-packages/google/cloud/client/__init__.py", line 287, in _determine_default
    return _determine_default_project(project)
  File "/home/***/.local/lib/python3.8/site-packages/google/cloud/_helpers/__init__.py", line 152, in _determine_default_project
    _, project = google.auth.default()
  File "/home/***/.local/lib/python3.8/site-packages/google/auth/_default.py", line 657, in default
    credentials, project_id = checker()
  File "/home/***/.local/lib/python3.8/site-packages/google/auth/_default.py", line 650, in <lambda>
    lambda: _get_explicit_environ_credentials(quota_project_id=quota_project_id),
  File "/home/***/.local/lib/python3.8/site-packages/google/auth/_default.py", line 270, in _get_explicit_environ_credentials
    credentials, project_id = load_credentials_from_file(
  File "/home/***/.local/lib/python3.8/site-packages/google/auth/_default.py", line 114, in load_credentials_from_file
    raise exceptions.DefaultCredentialsError(
google.auth.exceptions.DefaultCredentialsError: File /opt/***/credential.json was not found.
[2024-06-05T08:23:15.453+0000] {taskinstance.py:2698} ERROR - Task failed with exception
Traceback (most recent call last):
  File "/home/airflow/.local/lib/python3.8/site-packages/airflow/models/taskinstance.py", line 433, in _execute_task
    result = execute_callable(context=context, **execute_callable_kwargs)
  File "/home/airflow/.local/lib/python3.8/site-packages/airflow/operators/python.py", line 199, in execute
    return_value = self.execute_callable()
  File "/home/airflow/.local/lib/python3.8/site-packages/airflow/operators/python.py", line 216, in execute_callable
    return self.python_callable(*self.op_args, **self.op_kwargs)
  File "/opt/airflow/dags/bigquery_transform_python.py", line 27, in run_transform_script
    raise Exception("Script failed: " + result.stderr)
Exception: Script failed: Traceback (most recent call last):
  File "/opt/***/dags/network_model/dataprep.py", line 10, in <module>
    client = bigquery.Client()
  File "/home/***/.local/lib/python3.8/site-packages/google/cloud/bigquery/client.py", line 237, in __init__
    super(Client, self).__init__(
  File "/home/***/.local/lib/python3.8/site-packages/google/cloud/client/__init__.py", line 320, in __init__
    _ClientProjectMixin.__init__(self, project=project, credentials=credentials)
  File "/home/***/.local/lib/python3.8/site-packages/google/cloud/client/__init__.py", line 268, in __init__
    project = self._determine_default(project)
  File "/home/***/.local/lib/python3.8/site-packages/google/cloud/client/__init__.py", line 287, in _determine_default
    return _determine_default_project(project)
  File "/home/***/.local/lib/python3.8/site-packages/google/cloud/_helpers/__init__.py", line 152, in _determine_default_project
    _, project = google.auth.default()
  File "/home/***/.local/lib/python3.8/site-packages/google/auth/_default.py", line 657, in default
    credentials, project_id = checker()
  File "/home/***/.local/lib/python3.8/site-packages/google/auth/_default.py", line 650, in <lambda>
    lambda: _get_explicit_environ_credentials(quota_project_id=quota_project_id),
  File "/home/***/.local/lib/python3.8/site-packages/google/auth/_default.py", line 270, in _get_explicit_environ_credentials
    credentials, project_id = load_credentials_from_file(
  File "/home/***/.local/lib/python3.8/site-packages/google/auth/_default.py", line 114, in load_credentials_from_file
    raise exceptions.DefaultCredentialsError(
google.auth.exceptions.DefaultCredentialsError: File /opt/***/credential.json was not found.

[2024-06-05T08:23:15.469+0000] {taskinstance.py:1138} INFO - Marking task as FAILED. dag_id=bigquery_transform_python, task_id=run_transform_script, execution_date=20240605T081808, start_date=20240605T082313, end_date=20240605T082315
[2024-06-05T08:23:15.490+0000] {standard_task_runner.py:107} ERROR - Failed to execute job 1114 for task run_transform_script (Script failed: Traceback (most recent call last):
  File "/opt/***/dags/network_model/dataprep.py", line 10, in <module>
    client = bigquery.Client()
  File "/home/***/.local/lib/python3.8/site-packages/google/cloud/bigquery/client.py", line 237, in __init__
    super(Client, self).__init__(
  File "/home/***/.local/lib/python3.8/site-packages/google/cloud/client/__init__.py", line 320, in __init__
    _ClientProjectMixin.__init__(self, project=project, credentials=credentials)
  File "/home/***/.local/lib/python3.8/site-packages/google/cloud/client/__init__.py", line 268, in __init__
    project = self._determine_default(project)
  File "/home/***/.local/lib/python3.8/site-packages/google/cloud/client/__init__.py", line 287, in _determine_default
    return _determine_default_project(project)
  File "/home/***/.local/lib/python3.8/site-packages/google/cloud/_helpers/__init__.py", line 152, in _determine_default_project
    _, project = google.auth.default()
  File "/home/***/.local/lib/python3.8/site-packages/google/auth/_default.py", line 657, in default
    credentials, project_id = checker()
  File "/home/***/.local/lib/python3.8/site-packages/google/auth/_default.py", line 650, in <lambda>
    lambda: _get_explicit_environ_credentials(quota_project_id=quota_project_id),
  File "/home/***/.local/lib/python3.8/site-packages/google/auth/_default.py", line 270, in _get_explicit_environ_credentials
    credentials, project_id = load_credentials_from_file(
  File "/home/***/.local/lib/python3.8/site-packages/google/auth/_default.py", line 114, in load_credentials_from_file
    raise exceptions.DefaultCredentialsError(
google.auth.exceptions.DefaultCredentialsError: File /opt/***/credential.json was not found.
; 2790)
[2024-06-05T08:23:15.538+0000] {local_task_job_runner.py:234} INFO - Task exited with return code 1
[2024-06-05T08:23:15.557+0000] {taskinstance.py:3280} INFO - 0 downstream tasks scheduled from follow-on schedule check
