[2024-05-30T01:52:07.195+0000] {taskinstance.py:1956} INFO - Dependencies all met for dep_context=non-requeueable deps ti=<TaskInstance: dbt.dbt_run scheduled__2024-05-28T00:00:00+00:00 [queued]>
[2024-05-30T01:52:07.235+0000] {taskinstance.py:1956} INFO - Dependencies all met for dep_context=requeueable deps ti=<TaskInstance: dbt.dbt_run scheduled__2024-05-28T00:00:00+00:00 [queued]>
[2024-05-30T01:52:07.237+0000] {taskinstance.py:2170} INFO - Starting attempt 1 of 2
[2024-05-30T01:52:07.277+0000] {taskinstance.py:2191} INFO - Executing <Task(BashOperator): dbt_run> on 2024-05-28 00:00:00+00:00
[2024-05-30T01:52:07.290+0000] {standard_task_runner.py:60} INFO - Started process 8084 to run task
[2024-05-30T01:52:07.297+0000] {standard_task_runner.py:87} INFO - Running: ['***', 'tasks', 'run', 'dbt', 'dbt_run', 'scheduled__2024-05-28T00:00:00+00:00', '--job-id', '396', '--raw', '--subdir', 'DAGS_FOLDER/dbt.py', '--cfg-path', '/tmp/tmpmgfgz_s0']
[2024-05-30T01:52:07.303+0000] {standard_task_runner.py:88} INFO - Job 396: Subtask dbt_run
[2024-05-30T01:52:07.412+0000] {task_command.py:423} INFO - Running <TaskInstance: dbt.dbt_run scheduled__2024-05-28T00:00:00+00:00 [running]> on host dd00f1ab2b6c
[2024-05-30T01:52:07.676+0000] {taskinstance.py:2480} INFO - Exporting env vars: AIRFLOW_CTX_DAG_OWNER='***' AIRFLOW_CTX_DAG_ID='dbt' AIRFLOW_CTX_TASK_ID='dbt_run' AIRFLOW_CTX_EXECUTION_DATE='2024-05-28T00:00:00+00:00' AIRFLOW_CTX_TRY_NUMBER='1' AIRFLOW_CTX_DAG_RUN_ID='scheduled__2024-05-28T00:00:00+00:00'
[2024-05-30T01:52:07.684+0000] {subprocess.py:63} INFO - Tmp dir root location: /tmp
[2024-05-30T01:52:07.690+0000] {subprocess.py:75} INFO - Running command: ['/usr/bin/bash', '-c', 'dbt run --project-dir /opt/***/dags/dbt/network']
[2024-05-30T01:52:07.719+0000] {subprocess.py:86} INFO - Output:
[2024-05-30T01:52:07.738+0000] {subprocess.py:93} INFO - /usr/bin/bash: line 1: dbt: command not found
[2024-05-30T01:52:07.739+0000] {subprocess.py:97} INFO - Command exited with return code 127
[2024-05-30T01:52:07.767+0000] {taskinstance.py:2698} ERROR - Task failed with exception
Traceback (most recent call last):
  File "/home/airflow/.local/lib/python3.8/site-packages/airflow/models/taskinstance.py", line 433, in _execute_task
    result = execute_callable(context=context, **execute_callable_kwargs)
  File "/home/airflow/.local/lib/python3.8/site-packages/airflow/operators/bash.py", line 212, in execute
    raise AirflowException(
airflow.exceptions.AirflowException: Bash command failed. The command returned a non-zero exit code 127.
[2024-05-30T01:52:07.778+0000] {taskinstance.py:1138} INFO - Marking task as UP_FOR_RETRY. dag_id=dbt, task_id=dbt_run, execution_date=20240528T000000, start_date=20240530T015207, end_date=20240530T015207
[2024-05-30T01:52:07.806+0000] {standard_task_runner.py:107} ERROR - Failed to execute job 396 for task dbt_run (Bash command failed. The command returned a non-zero exit code 127.; 8084)
[2024-05-30T01:52:07.838+0000] {local_task_job_runner.py:234} INFO - Task exited with return code 1
[2024-05-30T01:52:07.898+0000] {taskinstance.py:3280} INFO - 0 downstream tasks scheduled from follow-on schedule check
