[2024-05-29T14:06:35.838+0000] {taskinstance.py:1956} INFO - Dependencies all met for dep_context=non-requeueable deps ti=<TaskInstance: dbt_test.run_dbt_model manual__2024-05-29T14:06:34.111436+00:00 [queued]>
[2024-05-29T14:06:35.854+0000] {taskinstance.py:1956} INFO - Dependencies all met for dep_context=requeueable deps ti=<TaskInstance: dbt_test.run_dbt_model manual__2024-05-29T14:06:34.111436+00:00 [queued]>
[2024-05-29T14:06:35.855+0000] {taskinstance.py:2170} INFO - Starting attempt 1 of 2
[2024-05-29T14:06:35.874+0000] {taskinstance.py:2191} INFO - Executing <Task(BashOperator): run_dbt_model> on 2024-05-29 14:06:34.111436+00:00
[2024-05-29T14:06:35.881+0000] {standard_task_runner.py:60} INFO - Started process 4926 to run task
[2024-05-29T14:06:35.886+0000] {standard_task_runner.py:87} INFO - Running: ['***', 'tasks', 'run', 'dbt_test', 'run_dbt_model', 'manual__2024-05-29T14:06:34.111436+00:00', '--job-id', '363', '--raw', '--subdir', 'DAGS_FOLDER/dbt_test.py', '--cfg-path', '/tmp/tmpqf006wnb']
[2024-05-29T14:06:35.890+0000] {standard_task_runner.py:88} INFO - Job 363: Subtask run_dbt_model
[2024-05-29T14:06:35.968+0000] {task_command.py:423} INFO - Running <TaskInstance: dbt_test.run_dbt_model manual__2024-05-29T14:06:34.111436+00:00 [running]> on host be0574dd2df3
[2024-05-29T14:06:36.081+0000] {taskinstance.py:2480} INFO - Exporting env vars: AIRFLOW_CTX_DAG_OWNER='***' AIRFLOW_CTX_DAG_ID='dbt_test' AIRFLOW_CTX_TASK_ID='run_dbt_model' AIRFLOW_CTX_EXECUTION_DATE='2024-05-29T14:06:34.111436+00:00' AIRFLOW_CTX_TRY_NUMBER='1' AIRFLOW_CTX_DAG_RUN_ID='manual__2024-05-29T14:06:34.111436+00:00'
[2024-05-29T14:06:36.084+0000] {subprocess.py:63} INFO - Tmp dir root location: /tmp
[2024-05-29T14:06:36.087+0000] {subprocess.py:75} INFO - Running command: ['/usr/bin/bash', '-c', 'cd C:\\learn-dbt\\learndbt\\models  && dbt run --models clean_network']
[2024-05-29T14:06:36.097+0000] {subprocess.py:86} INFO - Output:
[2024-05-29T14:06:36.099+0000] {subprocess.py:93} INFO - /usr/bin/bash: line 1: cd: C:learn-dbtlearndbtmodels: No such file or directory
[2024-05-29T14:06:36.100+0000] {subprocess.py:97} INFO - Command exited with return code 1
[2024-05-29T14:06:36.113+0000] {taskinstance.py:2698} ERROR - Task failed with exception
Traceback (most recent call last):
  File "/home/airflow/.local/lib/python3.8/site-packages/airflow/models/taskinstance.py", line 433, in _execute_task
    result = execute_callable(context=context, **execute_callable_kwargs)
  File "/home/airflow/.local/lib/python3.8/site-packages/airflow/operators/bash.py", line 212, in execute
    raise AirflowException(
airflow.exceptions.AirflowException: Bash command failed. The command returned a non-zero exit code 1.
[2024-05-29T14:06:36.116+0000] {taskinstance.py:1138} INFO - Marking task as UP_FOR_RETRY. dag_id=dbt_test, task_id=run_dbt_model, execution_date=20240529T140634, start_date=20240529T140635, end_date=20240529T140636
[2024-05-29T14:06:36.138+0000] {standard_task_runner.py:107} ERROR - Failed to execute job 363 for task run_dbt_model (Bash command failed. The command returned a non-zero exit code 1.; 4926)
[2024-05-29T14:06:36.181+0000] {local_task_job_runner.py:234} INFO - Task exited with return code 1
[2024-05-29T14:06:36.205+0000] {taskinstance.py:3280} INFO - 0 downstream tasks scheduled from follow-on schedule check
